Workbook

Sheet Hướng dẫn
A1: Onboarding Partner Tracker – Hướng dẫn nhanh
A2: Công cụ kiểm soát 8 bước onboarding partner (theo whiteboard 'On boarding partner').
A4: CÁCH DÙNG (4 bước)
A5: 1 | B5: Sheet 'Partner': nhập tên partner ở cột A (tối đa 50). Cột còn lại tự tính.
A6: 2 | B6: Sheet 'Task': mỗi dòng 1 task. Chọn Partner, chọn Mã task (danh sách lấy từ 'Mẫu task'), nhập Owner, Ngày giao, Trạng thái. Hạn = Ngày giao + SLA; cảnh báo tự hiện.
A7: 3 | B7: Sheet 'Chấm điểm': chấm checklist tech meeting (bước 5) cho từng partner → kết luận OK / chưa đạt tự ra.
A8: 4 | B8: Sheet 'Dashboard': xem tổng quan, task trễ, task bị chặn, partner đang ở bước nào.
A10: TÍNH NĂNG TỰ ĐỘNG
A11: • | B11: Trạng thái từng bước (Xong / Đang làm / Bị chặn / Chưa) của mỗi partner, bước hiện tại và % quy trình.
A12: • | B12: Cảnh báo task: TRỄ x ngày, Sắp đến hạn (≤ 3 ngày), Bị chặn, 'Bước trước chưa xong' khi làm vượt bước.
A13: • | B13: Chấm điểm có trọng số, tiêu chí bắt buộc và ngưỡng đạt → kết luận OK / Chưa đạt / Chưa chấm đủ.
A14: • | B14: Thêm task mới: điền dòng trống trong 'Mẫu task' (mã + bước + SLA); task đó xuất hiện trong danh sách chọn.
A16: QUY ƯỚC MÀU
A17: Chữ xanh + nền vàng nhạt | B17: Ô nhập liệu – được sửa.
A18: Chữ đen | B18: Công thức – không sửa.
A19: Chữ đỏ nghiêng | B19: Giả định cần xác nhận.
A21: DỮ LIỆU VÍ DỤ
A22: • | B22: 'Partner mẫu A' và 'Partner mẫu B' (cùng task và điểm mẫu) chỉ để minh hoạ. Xoá hoặc ghi đè khi dùng thật.
A23: • | B23: Để xoá ví dụ: xoá dữ liệu cột A, B, G, H, K, L, N ở sheet 'Task' (dòng 5–44), cột A–E ở 'Partner', cột D ở 'Chấm điểm'. Đừng xoá dòng (sẽ mất công thức).
A25: GIẢ ĐỊNH (chữ trên whiteboard khó đọc)
A26: • | B26: Bước 6 = 'Quyết định / duyệt'; MOA = bước 7; bước 8 = hoạt động sau ký (truyền thông, đóng gói VTF, đào tạo 2 chiều, biz matching, setup liên tục).
A27: • | B27: SLA từng task, tiêu chí và trọng số chấm điểm, ngưỡng đạt 70% là số đề xuất – cần team chốt (xem sheet 'Câu hỏi mở').
A28: • | B28: Ngày giao nhập tay; Hạn = Ngày giao + SLA. Cảnh báo dùng ngày hiện tại của máy (TODAY).

Sheet Dashboard
A1: Dashboard onboarding partner
A2: Tự cập nhật từ sheet 'Partner' và 'Task'. Không nhập tay ở sheet này.
A4: ="Cập nhật: "&TEXT(TODAY(),"dd/mm/yyyy") -> Cập nhật: 30/10/2026
A5: Tổng partner | B5: Đang triển khai | C5: Tổng task | D5: % task hoàn thành | E5: Task trễ hạn | F5: Task bị chặn | G5: Đến hạn trong 7 ngày
A6: =COUNTA(Partner!$A$5:$A$54) -> 2 | B6: =A6-COUNTIF(Partner!$U$5:$U$54,"Hoàn tất") -> 2 | C6: =COUNTA(Task!$B$5:$B$404)-COUNTIF(Task!$K$5:$K$404,"Không áp dụng") -> 40 | D6: =IF(C6=0,0,COUNTIF(Task!$K$5:$K$404,"Hoàn thành")/C6) -> 0.425 | E6: =SUM(Task!$O$5:$O$404) -> 1 | F6: =COUNTIF(Task!$K$5:$K$404,"Bị chặn") -> 1 | G6: =COUNTIFS(Task!$J$5:$J$404,">="&TODAY(),Task!$J$5:$J$404,"<="&TODAY()+7,Task!$K$5:$K$404,"<>Hoàn thành",Task!$K$5:$K$404,"<>Không áp dụng") -> 2
A8: Tiến độ theo bước
A9: # | B9: Bước | C9: Tổng task | D9: Xong | E9: Đang làm | F9: Bị chặn | G9: Trễ | H9: % xong | I9: Số partner đang ở bước
A10: 1 | B10: =INDEX('Quy trình'!$B$5:$B$12,$A10) -> Sourcing | C10: =COUNTIFS(Task!$C$5:$C$404,$A10)-COUNTIFS(Task!$C$5:$C$404,$A10,Task!$K$5:$K$404,"Không áp dụng") -> 8 | D10: =COUNTIFS(Task!$C$5:$C$404,$A10,Task!$K$5:$K$404,"Hoàn thành") -> 8 | E10: =COUNTIFS(Task!$C$5:$C$404,$A10,Task!$K$5:$K$404,"Đang làm") -> 0 | F10: =COUNTIFS(Task!$C$5:$C$404,$A10,Task!$K$5:$K$404,"Bị chặn") -> 0 | G10: =SUMIFS(Task!$O$5:$O$404,Task!$C$5:$C$404,$A10) -> 0 | H10: =IF(C10=0,0,D10/C10) -> 1 | I10: =COUNTIF(Partner!$N$5:$N$54,$A10) -> 0
A11: 2 | B11: =INDEX('Quy trình'!$B$5:$B$12,$A11) -> Approach | C11: =COUNTIFS(Task!$C$5:$C$404,$A11)-COUNTIFS(Task!$C$5:$C$404,$A11,Task!$K$5:$K$404,"Không áp dụng") -> 6 | D11: =COUNTIFS(Task!$C$5:$C$404,$A11,Task!$K$5:$K$404,"Hoàn thành") -> 4 | E11: =COUNTIFS(Task!$C$5:$C$404,$A11,Task!$K$5:$K$404,"Đang làm") -> 1 | F11: =COUNTIFS(Task!$C$5:$C$404,$A11,Task!$K$5:$K$404,"Bị chặn") -> 1 | G11: =SUMIFS(Task!$O$5:$O$404,Task!$C$5:$C$404,$A11) -> 0 | H11: =IF(C11=0,0,D11/C11) -> 0.66666667 | I11: =COUNTIF(Partner!$N$5:$N$54,$A11) -> 1
A12: 3 | B12: =INDEX('Quy trình'!$B$5:$B$12,$A12) -> NDA | C12: =COUNTIFS(Task!$C$5:$C$404,$A12)-COUNTIFS(Task!$C$5:$C$404,$A12,Task!$K$5:$K$404,"Không áp dụng") -> 3 | D12: =COUNTIFS(Task!$C$5:$C$404,$A12,Task!$K$5:$K$404,"Hoàn thành") -> 3 | E12: =COUNTIFS(Task!$C$5:$C$404,$A12,Task!$K$5:$K$404,"Đang làm") -> 0 | F12: =COUNTIFS(Task!$C$5:$C$404,$A12,Task!$K$5:$K$404,"Bị chặn") -> 0 | G12: =SUMIFS(Task!$O$5:$O$404,Task!$C$5:$C$404,$A12) -> 0 | H12: =IF(C12=0,0,D12/C12) -> 1 | I12: =COUNTIF(Partner!$N$5:$N$54,$A12) -> 0
A13: 4 | B13: =INDEX('Quy trình'!$B$5:$B$12,$A13) -> Hồ sơ của partner (A) | C13: =COUNTIFS(Task!$C$5:$C$404,$A13)-COUNTIFS(Task!$C$5:$C$404,$A13,Task!$K$5:$K$404,"Không áp dụng") -> 5 | D13: =COUNTIFS(Task!$C$5:$C$404,$A13,Task!$K$5:$K$404,"Hoàn thành") -> 2 | E13: =COUNTIFS(Task!$C$5:$C$404,$A13,Task!$K$5:$K$404,"Đang làm") -> 1 | F13: =COUNTIFS(Task!$C$5:$C$404,$A13,Task!$K$5:$K$404,"Bị chặn") -> 0 | G13: =SUMIFS(Task!$O$5:$O$404,Task!$C$5:$C$404,$A13) -> 1 | H13: =IF(C13=0,0,D13/C13) -> 0.4 | I13: =COUNTIF(Partner!$N$5:$N$54,$A13) -> 1
A14: 5 | B14: =INDEX('Quy trình'!$B$5:$B$12,$A14) -> Tech meeting | C14: =COUNTIFS(Task!$C$5:$C$404,$A14)-COUNTIFS(Task!$C$5:$C$404,$A14,Task!$K$5:$K$404,"Không áp dụng") -> 5 | D14: =COUNTIFS(Task!$C$5:$C$404,$A14,Task!$K$5:$K$404,"Hoàn thành") -> 0 | E14: =COUNTIFS(Task!$C$5:$C$404,$A14,Task!$K$5:$K$404,"Đang làm") -> 0 | F14: =COUNTIFS(Task!$C$5:$C$404,$A14,Task!$K$5:$K$404,"Bị chặn") -> 0 | G14: =SUMIFS(Task!$O$5:$O$404,Task!$C$5:$C$404,$A14) -> 0 | H14: =IF(C14=0,0,D14/C14) -> 0 | I14: =COUNTIF(Partner!$N$5:$N$54,$A14) -> 0
A15: 6 | B15: =INDEX('Quy trình'!$B$5:$B$12,$A15) -> Quyết định / duyệt (giả định) | C15: =COUNTIFS(Task!$C$5:$C$404,$A15)-COUNTIFS(Task!$C$5:$C$404,$A15,Task!$K$5:$K$404,"Không áp dụng") -> 2 | D15: =COUNTIFS(Task!$C$5:$C$404,$A15,Task!$K$5:$K$404,"Hoàn thành") -> 0 | E15: =COUNTIFS(Task!$C$5:$C$404,$A15,Task!$K$5:$K$404,"Đang làm") -> 0 | F15: =COUNTIFS(Task!$C$5:$C$404,$A15,Task!$K$5:$K$404,"Bị chặn") -> 0 | G15: =SUMIFS(Task!$O$5:$O$404,Task!$C$5:$C$404,$A15) -> 0 | H15: =IF(C15=0,0,D15/C15) -> 0 | I15: =COUNTIF(Partner!$N$5:$N$54,$A15) -> 0
A16: 7 | B16: =INDEX('Quy trình'!$B$5:$B$12,$A16) -> MOA | C16: =COUNTIFS(Task!$C$5:$C$404,$A16)-COUNTIFS(Task!$C$5:$C$404,$A16,Task!$K$5:$K$404,"Không áp dụng") -> 4 | D16: =COUNTIFS(Task!$C$5:$C$404,$A16,Task!$K$5:$K$404,"Hoàn thành") -> 0 | E16: =COUNTIFS(Task!$C$5:$C$404,$A16,Task!$K$5:$K$404,"Đang làm") -> 0 | F16: =COUNTIFS(Task!$C$5:$C$404,$A16,Task!$K$5:$K$404,"Bị chặn") -> 0 | G16: =SUMIFS(Task!$O$5:$O$404,Task!$C$5:$C$404,$A16) -> 0 | H16: =IF(C16=0,0,D16/C16) -> 0 | I16: =COUNTIF(Partner!$N$5:$N$54,$A16) -> 0
A17: 8 | B17: =INDEX('Quy trình'!$B$5:$B$12,$A17) -> Sau ký: vận hành liên tục | C17: =COUNTIFS(Task!$C$5:$C$404,$A17)-COUNTIFS(Task!$C$5:$C$404,$A17,Task!$K$5:$K$404,"Không áp dụng") -> 7 | D17: =COUNTIFS(Task!$C$5:$C$404,$A17,Task!$K$5:$K$404,"Hoàn thành") -> 0 | E17: =COUNTIFS(Task!$C$5:$C$404,$A17,Task!$K$5:$K$404,"Đang làm") -> 0 | F17: =COUNTIFS(Task!$C$5:$C$404,$A17,Task!$K$5:$K$404,"Bị chặn") -> 0 | G17: =SUMIFS(Task!$O$5:$O$404,Task!$C$5:$C$404,$A17) -> 0 | H17: =IF(C17=0,0,D17/C17) -> 0 | I17: =COUNTIF(Partner!$N$5:$N$54,$A17) -> 0
A19: Danh sách partner
A20: # | B20: Partner | C20: Bước hiện tại | D20: % quy trình | E20: Trạng thái chung | F20: Task trễ | G20: Kết quả tech meeting
A21: =IF(Partner!$A5="","",1) -> 1 | B21: =IF(Partner!$A5="","",Partner!$A5) -> Partner mẫu A (ví dụ – xoá/ghi đè) | C21: =IF(Partner!$A5="","",Partner!$O5) -> Hồ sơ của partner (A) | D21: =IF(Partner!$A5="","",Partner!$R5) -> 0.38235294 | E21: =IF(Partner!$A5="","",Partner!$U5) -> Có việc trễ | F21: =IF(Partner!$A5="","",Partner!$S5) -> 1 | G21: =IF(Partner!$A5="","",Partner!$V5) -> OK – đạt
A22: =IF(Partner!$A6="","",2) -> 2 | B22: =IF(Partner!$A6="","",Partner!$A6) -> Partner mẫu B (ví dụ – xoá/ghi đè) | C22: =IF(Partner!$A6="","",Partner!$O6) -> Approach | D22: =IF(Partner!$A6="","",Partner!$R6) -> 0.11764706 | E22: =IF(Partner!$A6="","",Partner!$U6) -> Bị chặn | F22: =IF(Partner!$A6="","",Partner!$S6) -> 0 | G22: =IF(Partner!$A6="","",Partner!$V6) -> Chưa chấm đủ
A23: =IF(Partner!$A7="","",3) | B23: =IF(Partner!$A7="","",Partner!$A7) | C23: =IF(Partner!$A7="","",Partner!$O7) | D23: =IF(Partner!$A7="","",Partner!$R7) | E23: =IF(Partner!$A7="","",Partner!$U7) | F23: =IF(Partner!$A7="","",Partner!$S7) | G23: =IF(Partner!$A7="","",Partner!$V7)
A24: =IF(Partner!$A8="","",4) | B24: =IF(Partner!$A8="","",Partner!$A8) | C24: =IF(Partner!$A8="","",Partner!$O8) | D24: =IF(Partner!$A8="","",Partner!$R8) | E24: =IF(Partner!$A8="","",Partner!$U8) | F24: =IF(Partner!$A8="","",Partner!$S8) | G24: =IF(Partner!$A8="","",Partner!$V8)
A25: =IF(Partner!$A9="","",5) | B25: =IF(Partner!$A9="","",Partner!$A9) | C25: =IF(Partner!$A9="","",Partner!$O9) | D25: =IF(Partner!$A9="","",Partner!$R9) | E25: =IF(Partner!$A9="","",Partner!$U9) | F25: =IF(Partner!$A9="","",Partner!$S9) | G25: =IF(Partner!$A9="","",Partner!$V9)
A26: =IF(Partner!$A10="","",6) | B26: =IF(Partner!$A10="","",Partner!$A10) | C26: =IF(Partner!$A10="","",Partner!$O10) | D26: =IF(Partner!$A10="","",Partner!$R10) | E26: =IF(Partner!$A10="","",Partner!$U10) | F26: =IF(Partner!$A10="","",Partner!$S10) | G26: =IF(Partner!$A10="","",Partner!$V10)
A27: =IF(Partner!$A11="","",7) | B27: =IF(Partner!$A11="","",Partner!$A11) | C27: =IF(Partner!$A11="","",Partner!$O11) | D27: =IF(Partner!$A11="","",Partner!$R11) | E27: =IF(Partner!$A11="","",Partner!$U11) | F27: =IF(Partner!$A11="","",Partner!$S11) | G27: =IF(Partner!$A11="","",Partner!$V11)
A28: =IF(Partner!$A12="","",8) | B28: =IF(Partner!$A12="","",Partner!$A12) | C28: =IF(Partner!$A12="","",Partner!$O12) | D28: =IF(Partner!$A12="","",Partner!$R12) | E28: =IF(Partner!$A12="","",Partner!$U12) | F28: =IF(Partner!$A12="","",Partner!$S12) | G28: =IF(Partner!$A12="","",Partner!$V12)
A29: =IF(Partner!$A13="","",9) | B29: =IF(Partner!$A13="","",Partner!$A13) | C29: =IF(Partner!$A13="","",Partner!$O13) | D29: =IF(Partner!$A13="","",Partner!$R13) | E29: =IF(Partner!$A13="","",Partner!$U13) | F29: =IF(Partner!$A13="","",Partner!$S13) | G29: =IF(Partner!$A13="","",Partner!$V13)
A30: =IF(Partner!$A14="","",10) | B30: =IF(Partner!$A14="","",Partner!$A14) | C30: =IF(Partner!$A14="","",Partner!$O14) | D30: =IF(Partner!$A14="","",Partner!$R14) | E30: =IF(Partner!$A14="","",Partner!$U14) | F30: =IF(Partner!$A14="","",Partner!$S14) | G30: =IF(Partner!$A14="","",Partner!$V14)
A31: =IF(Partner!$A15="","",11) | B31: =IF(Partner!$A15="","",Partner!$A15) | C31: =IF(Partner!$A15="","",Partner!$O15) | D31: =IF(Partner!$A15="","",Partner!$R15) | E31: =IF(Partner!$A15="","",Partner!$U15) | F31: =IF(Partner!$A15="","",Partner!$S15) | G31: =IF(Partner!$A15="","",Partner!$V15)
A32: =IF(Partner!$A16="","",12) | B32: =IF(Partner!$A16="","",Partner!$A16) | C32: =IF(Partner!$A16="","",Partner!$O16) | D32: =IF(Partner!$A16="","",Partner!$R16) | E32: =IF(Partner!$A16="","",Partner!$U16) | F32: =IF(Partner!$A16="","",Partner!$S16) | G32: =IF(Partner!$A16="","",Partner!$V16)
A33: =IF(Partner!$A17="","",13) | B33: =IF(Partner!$A17="","",Partner!$A17) | C33: =IF(Partner!$A17="","",Partner!$O17) | D33: =IF(Partner!$A17="","",Partner!$R17) | E33: =IF(Partner!$A17="","",Partner!$U17) | F33: =IF(Partner!$A17="","",Partner!$S17) | G33: =IF(Partner!$A17="","",Partner!$V17)
A34: =IF(Partner!$A18="","",14) | B34: =IF(Partner!$A18="","",Partner!$A18) | C34: =IF(Partner!$A18="","",Partner!$O18) | D34: =IF(Partner!$A18="","",Partner!$R18) | E34: =IF(Partner!$A18="","",Partner!$U18) | F34: =IF(Partner!$A18="","",Partner!$S18) | G34: =IF(Partner!$A18="","",Partner!$V18)
A35: =IF(Partner!$A19="","",15) | B35: =IF(Partner!$A19="","",Partner!$A19) | C35: =IF(Partner!$A19="","",Partner!$O19) | D35: =IF(Partner!$A19="","",Partner!$R19) | E35: =IF(Partner!$A19="","",Partner!$U19) | F35: =IF(Partner!$A19="","",Partner!$S19) | G35: =IF(Partner!$A19="","",Partner!$V19)
A36: Hiển thị 15 partner đầu trong sheet 'Partner'.

Sheet Partner
A1: Danh sách partner và tiến độ (tự tính từ sheet 'Task')
A2: Chỉ nhập cột A đến E (nền vàng). Các cột còn lại tự cập nhật. Chấm điểm tech meeting chỉ hỗ trợ 10 partner đầu.
E3: Mã bước → | F3: 1 | G3: 2 | H3: 3 | I3: 4 | J3: 5 | K3: 6 | L3: 7 | M3: 8
A4: Partner | B4: Ngành / sản phẩm | C4: Nguồn | D4: Owner | E4: Ngày bắt đầu | F4: B1 | G4: B2 | H4: B3 | I4: B4 | J4: B5 | K4: B6 | L4: B7 | M4: B8 | N4: Bước hiện tại (#) | O4: Bước hiện tại | P4: Tổng task | Q4: Đã xong | R4: % quy trình | S4: Task trễ | T4: Task bị chặn | U4: Trạng thái chung | V4: Kết quả tech meeting
A5: Partner mẫu A (ví dụ – xoá/ghi đè) | B5: An ninh mạng / DLP | C5: Giới thiệu | D5: BD | E5: 46251 | F5: =IF($A5="","",IF((COUNTIFS(Task!$A$5:$A$404,$A5,Task!$C$5:$C$404,F$3)-COUNTIFS(Task!$A$5:$A$404,$A5,Task!$C$5:$C$404,F$3,Task!$K$5:$K$404,"Không áp dụng"))=0,"–",IF(COUNTIFS(Task!$A$5:$A$404,$A5,Task!$C$5:$C$404,F$3,Task!$K$5:$K$404,"Hoàn thành")=(COUNTIFS(Task!$A$5:$A$404,$A5,Task!$C$5:$C$404,F$3)-COUNTIFS(Task!$A$5:$A$404,$A5,Task!$C$5:$C$404,F$3,Task!$K$5:$K$404,"Không áp dụng")),"Xong",IF(COUNTIFS(Task!$A$5:$A$404,$A5,Task!$C$5:$C$404,F$3,Task!$K$5:$K$404,"Bị chặn")>0,"Bị chặn",IF(COUNTIFS(Task!$A$5:$A$404,$A5,Task!$C$5:$C$404,F$3,Task!$K$5:$K$404,"Hoàn thành")+COUNTIFS(Task!$A$5:$A$404,$A5,Task!$C$5:$C$404,F$3,Task!$K$5:$K$404,"Đang làm")>0,"Đang làm","Chưa"))))) -> Xong | G5: =IF($A5="","",IF((COUNTIFS(Task!$A$5:$A$404,$A5,Task!$C$5:$C$404,G$3)-COUNTIFS(Task!$A$5:$A$404,$A5,Task!$C$5:$C$404,G$3,Task!$K$5:$K$404,"Không áp dụng"))=0,"–",IF(COUNTIFS(Task!$A$5:$A$404,$A5,Task!$C$5:$C$404,G$3,Task!$K$5:$K$404,"Hoàn thành")=(COUNTIFS(Task!$A$5:$A$404,$A5,Task!$C$5:$C$404,G$3)-COUNTIFS(Task!$A$5:$A$404,$A5,Task!$C$5:$C$404,G$3,Task!$K$5:$K$404,"Không áp dụng")),"Xong",IF(COUNTIFS(Task!$A$5:$A$404,$A5,Task!$C$5:$C$404,G$3,Task!$K$5:$K$404,"Bị chặn")>0,"Bị chặn",IF(COUNTIFS(Task!$A$5:$A$404,$A5,Task!$C$5:$C$404,G$3,Task!$K$5:$K$404,"Hoàn thành")+COUNTIFS(Task!$A$5:$A$404,$A5,Task!$C$5:$C$404,G$3,Task!$K$5:$K$404,"Đang làm")>0,"Đang làm","Chưa"))))) -> Xong | H5: =IF($A5="","",IF((COUNTIFS(Task!$A$5:$A$404,$A5,Task!$C$5:$C$404,H$3)-COUNTIFS(Task!$A$5:$A$404,$A5,Task!$C$5:$C$404,H$3,Task!$K$5:$K$404,"Không áp dụng"))=0,"–",IF(COUNTIFS(Task!$A$5:$A$404,$A5,Task!$C$5:$C$404,H$3,Task!$K$5:$K$404,"Hoàn thành")=(COUNTIFS(Task!$A$5:$A$404,$A5,Task!$C$5:$C$404,H$3)-COUNTIFS(Task!$A$5:$A$404,$A5,Task!$C$5:$C$404,H$3,Task!$K$5:$K$404,"Không áp dụng")),"Xong",IF(COUNTIFS(Task!$A$5:$A$404,$A5,Task!$C$5:$C$404,H$3,Task!$K$5:$K$404,"Bị chặn")>0,"Bị chặn",IF(COUNTIFS(Task!$A$5:$A$404,$A5,Task!$C$5:$C$404,H$3,Task!$K$5:$K$404,"Hoàn thành")+COUNTIFS(Task!$A$5:$A$404,$A5,Task!$C$5:$C$404,H$3,Task!$K$5:$K$404,"Đang làm")>0,"Đang làm","Chưa"))))) -> Xong | I5: =IF($A5="","",IF((COUNTIFS(Task!$A$5:$A$404,$A5,Task!$C$5:$C$404,I$3)-COUNTIFS(Task!$A$5:$A$404,$A5,Task!$C$5:$C$404,I$3,Task!$K$5:$K$404,"Không áp dụng"))=0,"–",IF(COUNTIFS(Task!$A$5:$A$404,$A5,Task!$C$5:$C$404,I$3,Task!$K$5:$K$404,"Hoàn thành")=(COUNTIFS(Task!$A$5:$A$404,$A5,Task!$C$5:$C$404,I$3)-COUNTIFS(Task!$A$5:$A$404,$A5,Task!$C$5:$C$404,I$3,Task!$K$5:$K$404,"Không áp dụng")),"Xong",IF(COUNTIFS(Task!$A$5:$A$404,$A5,Task!$C$5:$C$404,I$3,Task!$K$5:$K$404,"Bị chặn")>0,"Bị chặn",IF(COUNTIFS(Task!$A$5:$A$404,$A5,Task!$C$5:$C$404,I$3,Task!$K$5:$K$404,"Hoàn thành")+COUNTIFS(Task!$A$5:$A$404,$A5,Task!$C$5:$C$404,I$3,Task!$K$5:$K$404,"Đang làm")>0,"Đang làm","Chưa"))))) -> Đang làm | J5: =IF($A5="","",IF((COUNTIFS(Task!$A$5:$A$404,$A5,Task!$C$5:$C$404,J$3)-COUNTIFS(Task!$A$5:$A$404,$A5,Task!$C$5:$C$404,J$3,Task!$K$5:$K$404,"Không áp dụng"))=0,"–",IF(COUNTIFS(Task!$A$5:$A$404,$A5,Task!$C$5:$C$404,J$3,Task!$K$5:$K$404,"Hoàn thành")=(COUNTIFS(Task!$A$5:$A$404,$A5,Task!$C$5:$C$404,J$3)-COUNTIFS(Task!$A$5:$A$404,$A5,Task!$C$5:$C$404,J$3,Task!$K$5:$K$404,"Không áp dụng")),"Xong",IF(COUNTIFS(Task!$A$5:$A$404,$A5,Task!$C$5:$C$404,J$3,Task!$K$5:$K$404,"Bị chặn")>0,"Bị chặn",IF(COUNTIFS(Task!$A$5:$A$404,$A5,Task!$C$5:$C$404,J$3,Task!$K$5:$K$404,"Hoàn thành")+COUNTIFS(Task!$A$5:$A$404,$A5,Task!$C$5:$C$404,J$3,Task!$K$5:$K$404,"Đang làm")>0,"Đang làm","Chưa"))))) -> Chưa | K5: =IF($A5="","",IF((COUNTIFS(Task!$A$5:$A$404,$A5,Task!$C$5:$C$404,K$3)-COUNTIFS(Task!$A$5:$A$404,$A5,Task!$C$5:$C$404,K$3,Task!$K$5:$K$404,"Không áp dụng"))=0,"–",IF(COUNTIFS(Task!$A$5:$A$404,$A5,Task!$C$5:$C$404,K$3,Task!$K$5:$K$404,"Hoàn thành")=(COUNTIFS(Task!$A$5:$A$404,$A5,Task!$C$5:$C$404,K$3)-COUNTIFS(Task!$A$5:$A$404,$A5,Task!$C$5:$C$404,K$3,Task!$K$5:$K$404,"Không áp dụng")),"Xong",IF(COUNTIFS(Task!$A$5:$A$404,$A5,Task!$C$5:$C$404,K$3,Task!$K$5:$K$404,"Bị chặn")>0,"Bị chặn",IF(COUNTIFS(Task!$A$5:$A$404,$A5,Task!$C$5:$C$404,K$3,Task!$K$5:$K$404,"Hoàn thành")+COUNTIFS(Task!$A$5:$A$404,$A5,Task!$C$5:$C$404,K$3,Task!$K$5:$K$404,"Đang làm")>0,"Đang làm","Chưa"))))) -> Chưa | L5: =IF($A5="","",IF((COUNTIFS(Task!$A$5:$A$404,$A5,Task!$C$5:$C$404,L$3)-COUNTIFS(Task!$A$5:$A$404,$A5,Task!$C$5:$C$404,L$3,Task!$K$5:$K$404,"Không áp dụng"))=0,"–",IF(COUNTIFS(Task!$A$5:$A$404,$A5,Task!$C$5:$C$404,L$3,Task!$K$5:$K$404,"Hoàn thành")=(COUNTIFS(Task!$A$5:$A$404,$A5,Task!$C$5:$C$404,L$3)-COUNTIFS(Task!$A$5:$A$404,$A5,Task!$C$5:$C$404,L$3,Task!$K$5:$K$404,"Không áp dụng")),"Xong",IF(COUNTIFS(Task!$A$5:$A$404,$A5,Task!$C$5:$C$404,L$3,Task!$K$5:$K$404,"Bị chặn")>0,"Bị chặn",IF(COUNTIFS(Task!$A$5:$A$404,$A5,Task!$C$5:$C$404,L$3,Task!$K$5:$K$404,"Hoàn thành")+COUNTIFS(Task!$A$5:$A$404,$A5,Task!$C$5:$C$404,L$3,Task!$K$5:$K$404,"Đang làm")>0,"Đang làm","Chưa"))))) -> Chưa | M5: =IF($A5="","",IF((COUNTIFS(Task!$A$5:$A$404,$A5,Task!$C$5:$C$404,M$3)-COUNTIFS(Task!$A$5:$A$404,$A5,Task!$C$5:$C$404,M$3,Task!$K$5:$K$404,"Không áp dụng"))=0,"–",IF(COUNTIFS(Task!$A$5:$A$404,$A5,Task!$C$5:$C$404,M$3,Task!$K$5:$K$404,"Hoàn thành")=(COUNTIFS(Task!$A$5:$A$404,$A5,Task!$C$5:$C$404,M$3)-COUNTIFS(Task!$A$5:$A$404,$A5,Task!$C$5:$C$404,M$3,Task!$K$5:$K$404,"Không áp dụng")),"Xong",IF(COUNTIFS(Task!$A$5:$A$404,$A5,Task!$C$5:$C$404,M$3,Task!$K$5:$K$404,"Bị chặn")>0,"Bị chặn",IF(COUNTIFS(Task!$A$5:$A$404,$A5,Task!$C$5:$C$404,M$3,Task!$K$5:$K$404,"Hoàn thành")+COUNTIFS(Task!$A$5:$A$404,$A5,Task!$C$5:$C$404,M$3,Task!$K$5:$K$404,"Đang làm")>0,"Đang làm","Chưa"))))) -> Chưa | N5: =IF($A5="","",IF(F5<>"Xong",1,IF(G5<>"Xong",2,IF(H5<>"Xong",3,IF(I5<>"Xong",4,IF(J5<>"Xong",5,IF(K5<>"Xong",6,IF(L5<>"Xong",7,IF(M5<>"Xong",8,9))))))))) -> 4 | O5: =IF($A5="","",IF($N5=9,"Hoàn tất",INDEX('Quy trình'!$B$5:$B$12,$N5))) -> Hồ sơ của partner (A) | P5: =IF($A5="","",COUNTIFS(Task!$A$5:$A$404,$A5)-COUNTIFS(Task!$A$5:$A$404,$A5,Task!$K$5:$K$404,"Không áp dụng")) -> 34 | Q5: =IF($A5="","",COUNTIFS(Task!$A$5:$A$404,$A5,Task!$K$5:$K$404,"Hoàn thành")) -> 13 | R5: =IF($A5="","",Q5/MAX(P5,COUNTA('Mẫu task'!$A$5:$A$64))) -> 0.38235294 | S5: =IF($A5="","",SUMIFS(Task!$O$5:$O$404,Task!$A$5:$A$404,$A5)) -> 1 | T5: =IF($A5="","",COUNTIFS(Task!$A$5:$A$404,$A5,Task!$K$5:$K$404,"Bị chặn")) -> 0 | U5: =IF($A5="","",IF(P5=0,"Chưa có task",IF(T5>0,"Bị chặn",IF(S5>0,"Có việc trễ",IF(N5=9,"Hoàn tất","Đúng tiến độ"))))) -> Có việc trễ | V5: =IF($A5="","",IFERROR(INDEX('Chấm điểm'!$D$16:$M$16,MATCH($A5,'Chấm điểm'!$D$4:$M$4,0)),"")) -> OK – đạt
A6: Partner mẫu B (ví dụ – xoá/ghi đè) | B6: Cloud / Backup | C6: Sự kiện | D6: BD | E6: 46279 | F6: =IF($A6="","",IF((COUNTIFS(Task!$A$5:$A$404,$A6,Task!$C$5:$C$404,F$3)-COUNTIFS(Task!$A$5:$A$404,$A6,Task!$C$5:$C$404,F$3,Task!$K$5:$K$404,"Không áp dụng"))=0,"–",IF(COUNTIFS(Task!$A$5:$A$404,$A6,Task!$C$5:$C$404,F$3,Task!$K$5:$K$404,"Hoàn thành")=(COUNTIFS(Task!$A$5:$A$404,$A6,Task!$C$5:$C$404,F$3)-COUNTIFS(Task!$A$5:$A$404,$A6,Task!$C$5:$C$404,F$3,Task!$K$5:$K$404,"Không áp dụng")),"Xong",IF(COUNTIFS(Task!$A$5:$A$404,$A6,Task!$C$5:$C$404,F$3,Task!$K$5:$K$404,"Bị chặn")>0,"Bị chặn",IF(COUNTIFS(Task!$A$5:$A$404,$A6,Task!$C$5:$C$404,F$3,Task!$K$5:$K$404,"Hoàn thành")+COUNTIFS(Task!$A$5:$A$404,$A6,Task!$C$5:$C$404,F$3,Task!$K$5:$K$404,"Đang làm")>0,"Đang làm","Chưa"))))) -> Xong | G6: =IF($A6="","",IF((COUNTIFS(Task!$A$5:$A$404,$A6,Task!$C$5:$C$404,G$3)-COUNTIFS(Task!$A$5:$A$404,$A6,Task!$C$5:$C$404,G$3,Task!$K$5:$K$404,"Không áp dụng"))=0,"–",IF(COUNTIFS(Task!$A$5:$A$404,$A6,Task!$C$5:$C$404,G$3,Task!$K$5:$K$404,"Hoàn thành")=(COUNTIFS(Task!$A$5:$A$404,$A6,Task!$C$5:$C$404,G$3)-COUNTIFS(Task!$A$5:$A$404,$A6,Task!$C$5:$C$404,G$3,Task!$K$5:$K$404,"Không áp dụng")),"Xong",IF(COUNTIFS(Task!$A$5:$A$404,$A6,Task!$C$5:$C$404,G$3,Task!$K$5:$K$404,"Bị chặn")>0,"Bị chặn",IF(COUNTIFS(Task!$A$5:$A$404,$A6,Task!$C$5:$C$404,G$3,Task!$K$5:$K$404,"Hoàn thành")+COUNTIFS(Task!$A$5:$A$404,$A6,Task!$C$5:$C$404,G$3,Task!$K$5:$K$404,"Đang làm")>0,"Đang làm","Chưa"))))) -> Bị chặn | H6: =IF($A6="","",IF((COUNTIFS(Task!$A$5:$A$404,$A6,Task!$C$5:$C$404,H$3)-COUNTIFS(Task!$A$5:$A$404,$A6,Task!$C$5:$C$404,H$3,Task!$K$5:$K$404,"Không áp dụng"))=0,"–",IF(COUNTIFS(Task!$A$5:$A$404,$A6,Task!$C$5:$C$404,H$3,Task!$K$5:$K$404,"Hoàn thành")=(COUNTIFS(Task!$A$5:$A$404,$A6,Task!$C$5:$C$404,H$3)-COUNTIFS(Task!$A$5:$A$404,$A6,Task!$C$5:$C$404,H$3,Task!$K$5:$K$404,"Không áp dụng")),"Xong",IF(COUNTIFS(Task!$A$5:$A$404,$A6,Task!$C$5:$C$404,H$3,Task!$K$5:$K$404,"Bị chặn")>0,"Bị chặn",IF(COUNTIFS(Task!$A$5:$A$404,$A6,Task!$C$5:$C$404,H$3,Task!$K$5:$K$404,"Hoàn thành")+COUNTIFS(Task!$A$5:$A$404,$A6,Task!$C$5:$C$404,H$3,Task!$K$5:$K$404,"Đang làm")>0,"Đang làm","Chưa"))))) -> – | I6: =IF($A6="","",IF((COUNTIFS(Task!$A$5:$A$404,$A6,Task!$C$5:$C$404,I$3)-COUNTIFS(Task!$A$5:$A$404,$A6,Task!$C$5:$C$404,I$3,Task!$K$5:$K$404,"Không áp dụng"))=0,"–",IF(COUNTIFS(Task!$A$5:$A$404,$A6,Task!$C$5:$C$404,I$3,Task!$K$5:$K$404,"Hoàn thành")=(COUNTIFS(Task!$A$5:$A$404,$A6,Task!$C$5:$C$404,I$3)-COUNTIFS(Task!$A$5:$A$404,$A6,Task!$C$5:$C$404,I$3,Task!$K$5:$K$404,"Không áp dụng")),"Xong",IF(COUNTIFS(Task!$A$5:$A$404,$A6,Task!$C$5:$C$404,I$3,Task!$K$5:$K$404,"Bị chặn")>0,"Bị chặn",IF(COUNTIFS(Task!$A$5:$A$404,$A6,Task!$C$5:$C$404,I$3,Task!$K$5:$K$404,"Hoàn thành")+COUNTIFS(Task!$A$5:$A$404,$A6,Task!$C$5:$C$404,I$3,Task!$K$5:$K$404,"Đang làm")>0,"Đang làm","Chưa"))))) -> – | J6: =IF($A6="","",IF((COUNTIFS(Task!$A$5:$A$404,$A6,Task!$C$5:$C$404,J$3)-COUNTIFS(Task!$A$5:$A$404,$A6,Task!$C$5:$C$404,J$3,Task!$K$5:$K$404,"Không áp dụng"))=0,"–",IF(COUNTIFS(Task!$A$5:$A$404,$A6,Task!$C$5:$C$404,J$3,Task!$K$5:$K$404,"Hoàn thành")=(COUNTIFS(Task!$A$5:$A$404,$A6,Task!$C$5:$C$404,J$3)-COUNTIFS(Task!$A$5:$A$404,$A6,Task!$C$5:$C$404,J$3,Task!$K$5:$K$404,"Không áp dụng")),"Xong",IF(COUNTIFS(Task!$A$5:$A$404,$A6,Task!$C$5:$C$404,J$3,Task!$K$5:$K$404,"Bị chặn")>0,"Bị chặn",IF(COUNTIFS(Task!$A$5:$A$404,$A6,Task!$C$5:$C$404,J$3,Task!$K$5:$K$404,"Hoàn thành")+COUNTIFS(Task!$A$5:$A$404,$A6,Task!$C$5:$C$404,J$3,Task!$K$5:$K$404,"Đang làm")>0,"Đang làm","Chưa"))))) -> – | K6: =IF($A6="","",IF((COUNTIFS(Task!$A$5:$A$404,$A6,Task!$C$5:$C$404,K$3)-COUNTIFS(Task!$A$5:$A$404,$A6,Task!$C$5:$C$404,K$3,Task!$K$5:$K$404,"Không áp dụng"))=0,"–",IF(COUNTIFS(Task!$A$5:$A$404,$A6,Task!$C$5:$C$404,K$3,Task!$K$5:$K$404,"Hoàn thành")=(COUNTIFS(Task!$A$5:$A$404,$A6,Task!$C$5:$C$404,K$3)-COUNTIFS(Task!$A$5:$A$404,$A6,Task!$C$5:$C$404,K$3,Task!$K$5:$K$404,"Không áp dụng")),"Xong",IF(COUNTIFS(Task!$A$5:$A$404,$A6,Task!$C$5:$C$404,K$3,Task!$K$5:$K$404,"Bị chặn")>0,"Bị chặn",IF(COUNTIFS(Task!$A$5:$A$404,$A6,Task!$C$5:$C$404,K$3,Task!$K$5:$K$404,"Hoàn thành")+COUNTIFS(Task!$A$5:$A$404,$A6,Task!$C$5:$C$404,K$3,Task!$K$5:$K$404,"Đang làm")>0,"Đang làm","Chưa"))))) -> – | L6: =IF($A6="","",IF((COUNTIFS(Task!$A$5:$A$404,$A6,Task!$C$5:$C$404,L$3)-COUNTIFS(Task!$A$5:$A$404,$A6,Task!$C$5:$C$404,L$3,Task!$K$5:$K$404,"Không áp dụng"))=0,"–",IF(COUNTIFS(Task!$A$5:$A$404,$A6,Task!$C$5:$C$404,L$3,Task!$K$5:$K$404,"Hoàn thành")=(COUNTIFS(Task!$A$5:$A$404,$A6,Task!$C$5:$C$404,L$3)-COUNTIFS(Task!$A$5:$A$404,$A6,Task!$C$5:$C$404,L$3,Task!$K$5:$K$404,"Không áp dụng")),"Xong",IF(COUNTIFS(Task!$A$5:$A$404,$A6,Task!$C$5:$C$404,L$3,Task!$K$5:$K$404,"Bị chặn")>0,"Bị chặn",IF(COUNTIFS(Task!$A$5:$A$404,$A6,Task!$C$5:$C$404,L$3,Task!$K$5:$K$404,"Hoàn thành")+COUNTIFS(Task!$A$5:$A$404,$A6,Task!$C$5:$C$404,L$3,Task!$K$5:$K$404,"Đang làm")>0,"Đang làm","Chưa"))))) -> – | M6: =IF($A6="","",IF((COUNTIFS(Task!$A$5:$A$404,$A6,Task!$C$5:$C$404,M$3)-COUNTIFS(Task!$A$5:$A$404,$A6,Task!$C$5:$C$404,M$3,Task!$K$5:$K$404,"Không áp dụng"))=0,"–",IF(COUNTIFS(Task!$A$5:$A$404,$A6,Task!$C$5:$C$404,M$3,Task!$K$5:$K$404,"Hoàn thành")=(COUNTIFS(Task!$A$5:$A$404,$A6,Task!$C$5:$C$404,M$3)-COUNTIFS(Task!$A$5:$A$404,$A6,Task!$C$5:$C$404,M$3,Task!$K$5:$K$404,"Không áp dụng")),"Xong",IF(COUNTIFS(Task!$A$5:$A$404,$A6,Task!$C$5:$C$404,M$3,Task!$K$5:$K$404,"Bị chặn")>0,"Bị chặn",IF(COUNTIFS(Task!$A$5:$A$404,$A6,Task!$C$5:$C$404,M$3,Task!$K$5:$K$404,"Hoàn thành")+COUNTIFS(Task!$A$5:$A$404,$A6,Task!$C$5:$C$404,M$3,Task!$K$5:$K$404,"Đang làm")>0,"Đang làm","Chưa"))))) -> – | N6: =IF($A6="","",IF(F6<>"Xong",1,IF(G6<>"Xong",2,IF(H6<>"Xong",3,IF(I6<>"Xong",4,IF(J6<>"Xong",5,IF(K6<>"Xong",6,IF(L6<>"Xong",7,IF(M6<>"Xong",8,9))))))))) -> 2 | O6: =IF($A6="","",IF($N6=9,"Hoàn tất",INDEX('Quy trình'!$B$5:$B$12,$N6))) -> Approach | P6: =IF($A6="","",COUNTIFS(Task!$A$5:$A$404,$A6)-COUNTIFS(Task!$A$5:$A$404,$A6,Task!$K$5:$K$404,"Không áp dụng")) -> 6 | Q6: =IF($A6="","",COUNTIFS(Task!$A$5:$A$404,$A6,Task!$K$5:$K$404,"Hoàn thành")) -> 4 | R6: =IF($A6="","",Q6/MAX(P6,COUNTA('Mẫu task'!$A$5:$A$64))) -> 0.11764706 | S6: =IF($A6="","",SUMIFS(Task!$O$5:$O$404,Task!$A$5:$A$404,$A6)) -> 0 | T6: =IF($A6="","",COUNTIFS(Task!$A$5:$A$404,$A6,Task!$K$5:$K$404,"Bị chặn")) -> 1 | U6: =IF($A6="","",IF(P6=0,"Chưa có task",IF(T6>0,"Bị chặn",IF(S6>0,"Có việc trễ",IF(N6=9,"Hoàn tất","Đúng tiến độ"))))) -> Bị chặn | V6: =IF($A6="","",IFERROR(INDEX('Chấm điểm'!$D$16:$M$16,MATCH($A6,'Chấm điểm'!$D$4:$M$4,0)),"")) -> Chưa chấm đủ
F7: =IF($A7="","",IF((COUNTIFS(Task!$A$5:$A$404,$A7,Task!$C$5:$C$404,F$3)-COUNTIFS(Task!$A$5:$A$404,$A7,Task!$C$5:$C$404,F$3,Task!$K$5:$K$404,"Không áp dụng"))=0,"–",IF(COUNTIFS(Task!$A$5:$A$404,$A7,Task!$C$5:$C$404,F$3,Task!$K$5:$K$404,"Hoàn thành")=(COUNTIFS(Task!$A$5:$A$404,$A7,Task!$C$5:$C$404,F$3)-COUNTIFS(Task!$A$5:$A$404,$A7,Task!$C$5:$C$404,F$3,Task!$K$5:$K$404,"Không áp dụng")),"Xong",IF(COUNTIFS(Task!$A$5:$A$404,$A7,Task!$C$5:$C$404,F$3,Task!$K$5:$K$404,"Bị chặn")>0,"Bị chặn",IF(COUNTIFS(Task!$A$5:$A$404,$A7,Task!$C$5:$C$404,F$3,Task!$K$5:$K$404,"Hoàn thành")+COUNTIFS(Task!$A$5:$A$404,$A7,Task!$C$5:$C$404,F$3,Task!$K$5:$K$404,"Đang làm")>0,"Đang làm","Chưa"))))) | G7: =IF($A7="","",IF((COUNTIFS(Task!$A$5:$A$404,$A7,Task!$C$5:$C$404,G$3)-COUNTIFS(Task!$A$5:$A$404,$A7,Task!$C$5:$C$404,G$3,Task!$K$5:$K$404,"Không áp dụng"))=0,"–",IF(COUNTIFS(Task!$A$5:$A$404,$A7,Task!$C$5:$C$404,G$3,Task!$K$5:$K$404,"Hoàn thành")=(COUNTIFS(Task!$A$5:$A$404,$A7,Task!$C$5:$C$404,G$3)-COUNTIFS(Task!$A$5:$A$404,$A7,Task!$C$5:$C$404,G$3,Task!$K$5:$K$404,"Không áp dụng")),"Xong",IF(COUNTIFS(Task!$A$5:$A$404,$A7,Task!$C$5:$C$404,G$3,Task!$K$5:$K$404,"Bị chặn")>0,"Bị chặn",IF(COUNTIFS(Task!$A$5:$A$404,$A7,Task!$C$5:$C$404,G$3,Task!$K$5:$K$404,"Hoàn thành")+COUNTIFS(Task!$A$5:$A$404,$A7,Task!$C$5:$C$404,G$3,Task!$K$5:$K$404,"Đang làm")>0,"Đang làm","Chưa"))))) | H7: =IF($A7="","",IF((COUNTIFS(Task!$A$5:$A$404,$A7,Task!$C$5:$C$404,H$3)-COUNTIFS(Task!$A$5:$A$404,$A7,Task!$C$5:$C$404,H$3,Task!$K$5:$K$404,"Không áp dụng"))=0,"–",IF(COUNTIFS(Task!$A$5:$A$404,$A7,Task!$C$5:$C$404,H$3,Task!$K$5:$K$404,"Hoàn thành")=(COUNTIFS(Task!$A$5:$A$404,$A7,Task!$C$5:$C$404,H$3)-COUNTIFS(Task!$A$5:$A$404,$A7,Task!$C$5:$C$404,H$3,Task!$K$5:$K$404,"Không áp dụng")),"Xong",IF(COUNTIFS(Task!$A$5:$A$404,$A7,Task!$C$5:$C$404,H$3,Task!$K$5:$K$404,"Bị chặn")>0,"Bị chặn",IF(COUNTIFS(Task!$A$5:$A$404,$A7,Task!$C$5:$C$404,H$3,Task!$K$5:$K$404,"Hoàn thành")+COUNTIFS(Task!$A$5:$A$404,$A7,Task!$C$5:$C$404,H$3,Task!$K$5:$K$404,"Đang làm")>0,"Đang làm","Chưa"))))) | I7: =IF($A7="","",IF((COUNTIFS(Task!$A$5:$A$404,$A7,Task!$C$5:$C$404,I$3)-COUNTIFS(Task!$A$5:$A$404,$A7,Task!$C$5:$C$404,I$3,Task!$K$5:$K$404,"Không áp dụng"))=0,"–",IF(COUNTIFS(Task!$A$5:$A$404,$A7,Task!$C$5:$C$404,I$3,Task!$K$5:$K$404,"Hoàn thành")=(COUNTIFS(Task!$A$5:$A$404,$A7,Task!$C$5:$C$404,I$3)-COUNTIFS(Task!$A$5:$A$404,$A7,Task!$C$5:$C$404,I$3,Task!$K$5:$K$404,"Không áp dụng")),"Xong",IF(COUNTIFS(Task!$A$5:$A$404,$A7,Task!$C$5:$C$404,I$3,Task!$K$5:$K$404,"Bị chặn")>0,"Bị chặn",IF(COUNTIFS(Task!$A$5:$A$404,$A7,Task!$C$5:$C$404,I$3,Task!$K$5:$K$404,"Hoàn thành")+COUNTIFS(Task!$A$5:$A$404,$A7,Task!$C$5:$C$404,I$3,Task!$K$5:$K$404,"Đang làm")>0,"Đang làm","Chưa"))))) | J7: =IF($A7="","",IF((COUNTIFS(Task!$A$5:$A$404,$A7,Task!$C$5:$C$404,J$3)-COUNTIFS(Task!$A$5:$A$404,$A7,Task!$C$5:$C$404,J$3,Task!$K$5:$K$404,"Không áp dụng"))=0,"–",IF(COUNTIFS(Task!$A$5:$A$404,$A7,Task!$C$5:$C$404,J$3,Task!$K$5:$K$404,"Hoàn thành")=(COUNTIFS(Task!$A$5:$A$404,$A7,Task!$C$5:$C$404,J$3)-COUNTIFS(Task!$A$5:$A$404,$A7,Task!$C$5:$C$404,J$3,Task!$K$5:$K$404,"Không áp dụng")),"Xong",IF(COUNTIFS(Task!$A$5:$A$404,$A7,Task!$C$5:$C$404,J$3,Task!$K$5:$K$404,"Bị chặn")>0,"Bị chặn",IF(COUNTIFS(Task!$A$5:$A$404,$A7,Task!$C$5:$C$404,J$3,Task!$K$5:$K$404,"Hoàn thành")+COUNTIFS(Task!$A$5:$A$404,$A7,Task!$C$5:$C$404,J$3,Task!$K$5:$K$404,"Đang làm")>0,"Đang làm","Chưa"))))) | K7: =IF($A7="","",IF((COUNTIFS(Task!$A$5:$A$404,$A7,Task!$C$5:$C$404,K$3)-COUNTIFS(Task!$A$5:$A$404,$A7,Task!$C$5:$C$404,K$3,Task!$K$5:$K$404,"Không áp dụng"))=0,"–",IF(COUNTIFS(Task!$A$5:$A$404,$A7,Task!$C$5:$C$404,K$3,Task!$K$5:$K$404,"Hoàn thành")=(COUNTIFS(Task!$A$5:$A$404,$A7,Task!$C$5:$C$404,K$3)-COUNTIFS(Task!$A$5:$A$404,$A7,Task!$C$5:$C$404,K$3,Task!$K$5:$K$404,"Không áp dụng")),"Xong",IF(COUNTIFS(Task!$A$5:$A$404,$A7,Task!$C$5:$C$404,K$3,Task!$K$5:$K$404,"Bị chặn")>0,"Bị chặn",IF(COUNTIFS(Task!$A$5:$A$404,$A7,Task!$C$5:$C$404,K$3,Task!$K$5:$K$404,"Hoàn thành")+COUNTIFS(Task!$A$5:$A$404,$A7,Task!$C$5:$C$404,K$3,Task!$K$5:$K$404,"Đang làm")>0,"Đang làm","Chưa"))))) | L7: =IF($A7="","",IF((COUNTIFS(Task!$A$5:$A$404,$A7,Task!$C$5:$C$404,L$3)-COUNTIFS(Task!$A$5:$A$404,$A7,Task!$C$5:$C$404,L$3,Task!$K$5:$K$404,"Không áp dụng"))=0,"–",IF(COUNTIFS(Task!$A$5:$A$404,$A7,Task!$C$5:$C$404,L$3,Task!$K$5:$K$404,"Hoàn thành")=(COUNTIFS(Task!$A$5:$A$404,$A7,Task!$C$5:$C$404,L$3)-COUNTIFS(Task!$A$5:$A$404,$A7,Task!$C$5:$C$404,L$3,Task!$K$5:$K$404,"Không áp dụng")),"Xong",IF(COUNTIFS(Task!$A$5:$A$404,$A7,Task!$C$5:$C$404,L$3,Task!$K$5:$K$404,"Bị chặn")>0,"Bị chặn",IF(COUNTIFS(Task!$A$5:$A$404,$A7,Task!$C$5:$C$404,L$3,Task!$K$5:$K$404,"Hoàn thành")+COUNTIFS(Task!$A$5:$A$404,$A7,Task!$C$5:$C$404,L$3,Task!$K$5:$K$404,"Đang làm")>0,"Đang làm","Chưa"))))) | M7: =IF($A7="","",IF((COUNTIFS(Task!$A$5:$A$404,$A7,Task!$C$5:$C$404,M$3)-COUNTIFS(Task!$A$5:$A$404,$A7,Task!$C$5:$C$404,M$3,Task!$K$5:$K$404,"Không áp dụng"))=0,"–",IF(COUNTIFS(Task!$A$5:$A$404,$A7,Task!$C$5:$C$404,M$3,Task!$K$5:$K$404,"Hoàn thành")=(COUNTIFS(Task!$A$5:$A$404,$A7,Task!$C$5:$C$404,M$3)-COUNTIFS(Task!$A$5:$A$404,$A7,Task!$C$5:$C$404,M$3,Task!$K$5:$K$404,"Không áp dụng")),"Xong",IF(COUNTIFS(Task!$A$5:$A$404,$A7,Task!$C$5:$C$404,M$3,Task!$K$5:$K$404,"Bị chặn")>0,"Bị chặn",IF(COUNTIFS(Task!$A$5:$A$404,$A7,Task!$C$5:$C$404,M$3,Task!$K$5:$K$404,"Hoàn thành")+COUNTIFS(Task!$A$5:$A$404,$A7,Task!$C$5:$C$404,M$3,Task!$K$5:$K$404,"Đang làm")>0,"Đang làm","Chưa"))))) | N7: =IF($A7="","",IF(F7<>"Xong",1,IF(G7<>"Xong",2,IF(H7<>"Xong",3,IF(I7<>"Xong",4,IF(J7<>"Xong",5,IF(K7<>"Xong",6,IF(L7<>"Xong",7,IF(M7<>"Xong",8,9))))))))) | O7: =IF($A7="","",IF($N7=9,"Hoàn tất",INDEX('Quy trình'!$B$5:$B$12,$N7))) | P7: =IF($A7="","",COUNTIFS(Task!$A$5:$A$404,$A7)-COUNTIFS(Task!$A$5:$A$404,$A7,Task!$K$5:$K$404,"Không áp dụng")) | Q7: =IF($A7="","",COUNTIFS(Task!$A$5:$A$404,$A7,Task!$K$5:$K$404,"Hoàn thành")) | R7: =IF($A7="","",Q7/MAX(P7,COUNTA('Mẫu task'!$A$5:$A$64))) | S7: =IF($A7="","",SUMIFS(Task!$O$5:$O$404,Task!$A$5:$A$404,$A7)) | T7: =IF($A7="","",COUNTIFS(Task!$A$5:$A$404,$A7,Task!$K$5:$K$404,"Bị chặn")) | U7: =IF($A7="","",IF(P7=0,"Chưa có task",IF(T7>0,"Bị chặn",IF(S7>0,"Có việc trễ",IF(N7=9,"Hoàn tất","Đúng tiến độ"))))) | V7: =IF($A7="","",IFERROR(INDEX('Chấm điểm'!$D$16:$M$16,MATCH($A7,'Chấm điểm'!$D$4:$M$4,0)),""))
F8: =IF($A8="","",IF((COUNTIFS(Task!$A$5:$A$404,$A8,Task!$C$5:$C$404,F$3)-COUNTIFS(Task!$A$5:$A$404,$A8,Task!$C$5:$C$404,F$3,Task!$K$5:$K$404,"Không áp dụng"))=0,"–",IF(COUNTIFS(Task!$A$5:$A$404,$A8,Task!$C$5:$C$404,F$3,Task!$K$5:$K$404,"Hoàn thành")=(COUNTIFS(Task!$A$5:$A$404,$A8,Task!$C$5:$C$404,F$3)-COUNTIFS(Task!$A$5:$A$404,$A8,Task!$C$5:$C$404,F$3,Task!$K$5:$K$404,"Không áp dụng")),"Xong",IF(COUNTIFS(Task!$A$5:$A$404,$A8,Task!$C$5:$C$404,F$3,Task!$K$5:$K$404,"Bị chặn")>0,"Bị chặn",IF(COUNTIFS(Task!$A$5:$A$404,$A8,Task!$C$5:$C$404,F$3,Task!$K$5:$K$404,"Hoàn thành")+COUNTIFS(Task!$A$5:$A$404,$A8,Task!$C$5:$C$404,F$3,Task!$K$5:$K$404,"Đang làm")>0,"Đang làm","Chưa"))))) | G8: =IF($A8="","",IF((COUNTIFS(Task!$A$5:$A$404,$A8,Task!$C$5:$C$404,G$3)-COUNTIFS(Task!$A$5:$A$404,$A8,Task!$C$5:$C$404,G$3,Task!$K$5:$K$404,"Không áp dụng"))=0,"–",IF(COUNTIFS(Task!$A$5:$A$404,$A8,Task!$C$5:$C$404,G$3,Task!$K$5:$K$404,"Hoàn thành")=(COUNTIFS(Task!$A$5:$A$404,$A8,Task!$C$5:$C$404,G$3)-COUNTIFS(Task!$A$5:$A$404,$A8,Task!$C$5:$C$404,G$3,Task!$K$5:$K$404,"Không áp dụng")),"Xong",IF(COUNTIFS(Task!$A$5:$A$404,$A8,Task!$C$5:$C$404,G$3,Task!$K$5:$K$404,"Bị chặn")>0,"Bị chặn",IF(COUNTIFS(Task!$A$5:$A$404,$A8,Task!$C$5:$C$404,G$3,Task!$K$5:$K$404,"Hoàn thành")+COUNTIFS(Task!$A$5:$A$404,$A8,Task!$C$5:$C$404,G$3,Task!$K$5:$K$404,"Đang làm")>0,"Đang làm","Chưa"))))) | H8: =IF($A8="","",IF((COUNTIFS(Task!$A$5:$A$404,$A8,Task!$C$5:$C$404,H$3)-COUNTIFS(Task!$A$5:$A$404,$A8,Task!$C$5:$C$404,H$3,Task!$K$5:$K$404,"Không áp dụng"))=0,"–",IF(COUNTIFS(Task!$A$5:$A$404,$A8,Task!$C$5:$C$404,H$3,Task!$K$5:$K$404,"Hoàn thành")=(COUNTIFS(Task!$A$5:$A$404,$A8,Task!$C$5:$C$404,H$3)-COUNTIFS(Task!$A$5:$A$404,$A8,Task!$C$5:$C$404,H$3,Task!$K$5:$K$404,"Không áp dụng")),"Xong",IF(COUNTIFS(Task!$A$5:$A$404,$A8,Task!$C$5:$C$404,H$3,Task!$K$5:$K$404,"Bị chặn")>0,"Bị chặn",IF(COUNTIFS(Task!$A$5:$A$404,$A8,Task!$C$5:$C$404,H$3,Task!$K$5:$K$404,"Hoàn thành")+COUNTIFS(Task!$A$5:$A$404,$A8,Task!$C$5:$C$404,H$3,Task!$K$5:$K$404,"Đang làm")>0,"Đang làm","Chưa"))))) | I8: =IF($A8="","",IF((COUNTIFS(Task!$A$5:$A$404,$A8,Task!$C$5:$C$404,I$3)-COUNTIFS(Task!$A$5:$A$404,$A8,Task!$C$5:$C$404,I$3,Task!$K$5:$K$404,"Không áp dụng"))=0,"–",IF(COUNTIFS(Task!$A$5:$A$404,$A8,Task!$C$5:$C$404,I$3,Task!$K$5:$K$404,"Hoàn thành")=(COUNTIFS(Task!$A$5:$A$404,$A8,Task!$C$5:$C$404,I$3)-COUNTIFS(Task!$A$5:$A$404,$A8,Task!$C$5:$C$404,I$3,Task!$K$5:$K$404,"Không áp dụng")),"Xong",IF(COUNTIFS(Task!$A$5:$A$404,$A8,Task!$C$5:$C$404,I$3,Task!$K$5:$K$404,"Bị chặn")>0,"Bị chặn",IF(COUNTIFS(Task!$A$5:$A$404,$A8,Task!$C$5:$C$404,I$3,Task!$K$5:$K$404,"Hoàn thành")+COUNTIFS(Task!$A$5:$A$404,$A8,Task!$C$5:$C$404,I$3,Task!$K$5:$K$404,"Đang làm")>0,"Đang làm","Chưa"))))) | J8: =IF($A8="","",IF((COUNTIFS(Task!$A$5:$A$404,$A8,Task!$C$5:$C$404,J$3)-COUNTIFS(Task!$A$5:$A$404,$A8,Task!$C$5:$C$404,J$3,Task!$K$5:$K$404,"Không áp dụng"))=0,"–",IF(COUNTIFS(Task!$A$5:$A$404,$A8,Task!$C$5:$C$404,J$3,Task!$K$5:$K$404,"Hoàn thành")=(COUNTIFS(Task!$A$5:$A$404,$A8,Task!$C$5:$C$404,J$3)-COUNTIFS(Task!$A$5:$A$404,$A8,Task!$C$5:$C$404,J$3,Task!$K$5:$K$404,"Không áp dụng")),"Xong",IF(COUNTIFS(Task!$A$5:$A$404,$A8,Task!$C$5:$C$404,J$3,Task!$K$5:$K$404,"Bị chặn")>0,"Bị chặn",IF(COUNTIFS(Task!$A$5:$A$404,$A8,Task!$C$5:$C$404,J$3,Task!$K$5:$K$404,"Hoàn thành")+COUNTIFS(Task!$A$5:$A$404,$A8,Task!$C$5:$C$404,J$3,Task!$K$5:$K$404,"Đang làm")>0,"Đang làm","Chưa"))))) | K8: =IF($A8="","",IF((COUNTIFS(Task!$A$5:$A$404,$A8,Task!$C$5:$C$404,K$3)-COUNTIFS(Task!$A$5:$A$404,$A8,Task!$C$5:$C$404,K$3,Task!$K$5:$K$404,"Không áp dụng"))=0,"–",IF(COUNTIFS(Task!$A$5:$A$404,$A8,Task!$C$5:$C$404,K$3,Task!$K$5:$K$404,"Hoàn thành")=(COUNTIFS(Task!$A$5:$A$404,$A8,Task!$C$5:$C$404,K$3)-COUNTIFS(Task!$A$5:$A$404,$A8,Task!$C$5:$C$404,K$3,Task!$K$5:$K$404,"Không áp dụng")),"Xong",IF(COUNTIFS(Task!$A$5:$A$404,$A8,Task!$C$5:$C$404,K$3,Task!$K$5:$K$404,"Bị chặn")>0,"Bị chặn",IF(COUNTIFS(Task!$A$5:$A$404,$A8,Task!$C$5:$C$404,K$3,Task!$K$5:$K$404,"Hoàn thành")+COUNTIFS(Task!$A$5:$A$404,$A8,Task!$C$5:$C$404,K$3,Task!$K$5:$K$404,"Đang làm")>0,"Đang làm","Chưa"))))) | L8: =IF($A8="","",IF((COUNTIFS(Task!$A$5:$A$404,$A8,Task!$C$5:$C$404,L$3)-COUNTIFS(Task!$A$5:$A$404,$A8,Task!$C$5:$C$404,L$3,Task!$K$5:$K$404,"Không áp dụng"))=0,"–",IF(COUNTIFS(Task!$A$5:$A$404,$A8,Task!$C$5:$C$404,L$3,Task!$K$5:$K$404,"Hoàn thành")=(COUNTIFS(Task!$A$5:$A$404,$A8,Task!$C$5:$C$404,L$3)-COUNTIFS(Task!$A$5:$A$404,$A8,Task!$C$5:$C$404,L$3,Task!$K$5:$K$404,"Không áp dụng")),"Xong",IF(COUNTIFS(Task!$A$5:$A$404,$A8,Task!$C$5:$C$404,L$3,Task!$K$5:$K$404,"Bị chặn")>0,"Bị chặn",IF(COUNTIFS(Task!$A$5:$A$404,$A8,Task!$C$5:$C$404,L$3,Task!$K$5:$K$404,"Hoàn thành")+COUNTIFS(Task!$A$5:$A$404,$A8,Task!$C$5:$C$404,L$3,Task!$K$5:$K$404,"Đang làm")>0,"Đang làm","Chưa"))))) | M8: =IF($A8="","",IF((COUNTIFS(Task!$A$5:$A$404,$A8,Task!$C$5:$C$404,M$3)-COUNTIFS(Task!$A$5:$A$404,$A8,Task!$C$5:$C$404,M$3,Task!$K$5:$K$404,"Không áp dụng"))=0,"–",IF(COUNTIFS(Task!$A$5:$A$404,$A8,Task!$C$5:$C$404,M$3,Task!$K$5:$K$404,"Hoàn thành")=(COUNTIFS(Task!$A$5:$A$404,$A8,Task!$C$5:$C$404,M$3)-COUNTIFS(Task!$A$5:$A$404,$A8,Task!$C$5:$C$404,M$3,Task!$K$5:$K$404,"Không áp dụng")),"Xong",IF(COUNTIFS(Task!$A$5:$A$404,$A8,Task!$C$5:$C$404,M$3,Task!$K$5:$K$404,"Bị chặn")>0,"Bị chặn",IF(COUNTIFS(Task!$A$5:$A$404,$A8,Task!$C$5:$C$404,M$3,Task!$K$5:$K$404,"Hoàn thành")+COUNTIFS(Task!$A$5:$A$404,$A8,Task!$C$5:$C$404,M$3,Task!$K$5:$K$404,"Đang làm")>0,"Đang làm","Chưa"))))) | N8: =IF($A8="","",IF(F8<>"Xong",1,IF(G8<>"Xong",2,IF(H8<>"Xong",3,IF(I8<>"Xong",4,IF(J8<>"Xong",5,IF(K8<>"Xong",6,IF(L8<>"Xong",7,IF(M8<>"Xong",8,9))))))))) | O8: =IF($A8="","",IF($N8=9,"Hoàn tất",INDEX('Quy trình'!$B$5:$B$12,$N8))) | P8: =IF($A8="","",COUNTIFS(Task!$A$5:$A$404,$A8)-COUNTIFS(Task!$A$5:$A$404,$A8,Task!$K$5:$K$404,"Không áp dụng")) | Q8: =IF($A8="","",COUNTIFS(Task!$A$5:$A$404,$A8,Task!$K$5:$K$404,"Hoàn thành")) | R8: =IF($A8="","",Q8/MAX(P8,COUNTA('Mẫu task'!$A$5:$A$64))) | S8: =IF($A8="","",SUMIFS(Task!$O$5:$O$404,Task!$A$5:$A$404,$A8)) | T8: =IF($A8="","",COUNTIFS(Task!$A$5:$A$404,$A8,Task!$K$5:$K$404,"Bị chặn")) | U8: =IF($A8="","",IF(P8=0,"Chưa có task",IF(T8>0,"Bị chặn",IF(S8>0,"Có việc trễ",IF(N8=9,"Hoàn tất","Đúng tiến độ"))))) | V8: =IF($A8="","",IFERROR(INDEX('Chấm điểm'!$D$16:$M$16,MATCH($A8,'Chấm điểm'!$D$4:$M$4,0)),""))
F9: =IF($A9="","",IF((COUNTIFS(Task!$A$5:$A$404,$A9,Task!$C$5:$C$404,F$3)-COUNTIFS(Task!$A$5:$A$404,$A9,Task!$C$5:$C$404,F$3,Task!$K$5:$K$404,"Không áp dụng"))=0,"–",IF(COUNTIFS(Task!$A$5:$A$404,$A9,Task!$C$5:$C$404,F$3,Task!$K$5:$K$404,"Hoàn thành")=(COUNTIFS(Task!$A$5:$A$404,$A9,Task!$C$5:$C$404,F$3)-COUNTIFS(Task!$A$5:$A$404,$A9,Task!$C$5:$C$404,F$3,Task!$K$5:$K$404,"Không áp dụng")),"Xong",IF(COUNTIFS(Task!$A$5:$A$404,$A9,Task!$C$5:$C$404,F$3,Task!$K$5:$K$404,"Bị chặn")>0,"Bị chặn",IF(COUNTIFS(Task!$A$5:$A$404,$A9,Task!$C$5:$C$404,F$3,Task!$K$5:$K$404,"Hoàn thành")+COUNTIFS(Task!$A$5:$A$404,$A9,Task!$C$5:$C$404,F$3,Task!$K$5:$K$404,"Đang làm")>0,"Đang làm","Chưa"))))) | G9: =IF($A9="","",IF((COUNTIFS(Task!$A$5:$A$404,$A9,Task!$C$5:$C$404,G$3)-COUNTIFS(Task!$A$5:$A$404,$A9,Task!$C$5:$C$404,G$3,Task!$K$5:$K$404,"Không áp dụng"))=0,"–",IF(COUNTIFS(Task!$A$5:$A$404,$A9,Task!$C$5:$C$404,G$3,Task!$K$5:$K$404,"Hoàn thành")=(COUNTIFS(Task!$A$5:$A$404,$A9,Task!$C$5:$C$404,G$3)-COUNTIFS(Task!$A$5:$A$404,$A9,Task!$C$5:$C$404,G$3,Task!$K$5:$K$404,"Không áp dụng")),"Xong",IF(COUNTIFS(Task!$A$5:$A$404,$A9,Task!$C$5:$C$404,G$3,Task!$K$5:$K$404,"Bị chặn")>0,"Bị chặn",IF(COUNTIFS(Task!$A$5:$A$404,$A9,Task!$C$5:$C$404,G$3,Task!$K$5:$K$404,"Hoàn thành")+COUNTIFS(Task!$A$5:$A$404,$A9,Task!$C$5:$C$404,G$3,Task!$K$5:$K$404,"Đang làm")>0,"Đang làm","Chưa"))))) | H9: =IF($A9="","",IF((COUNTIFS(Task!$A$5:$A$404,$A9,Task!$C$5:$C$404,H$3)-COUNTIFS(Task!$A$5:$A$404,$A9,Task!$C$5:$C$404,H$3,Task!$K$5:$K$404,"Không áp dụng"))=0,"–",IF(COUNTIFS(Task!$A$5:$A$404,$A9,Task!$C$5:$C$404,H$3,Task!$K$5:$K$404,"Hoàn thành")=(COUNTIFS(Task!$A$5:$A$404,$A9,Task!$C$5:$C$404,H$3)-COUNTIFS(Task!$A$5:$A$404,$A9,Task!$C$5:$C$404,H$3,Task!$K$5:$K$404,"Không áp dụng")),"Xong",IF(COUNTIFS(Task!$A$5:$A$404,$A9,Task!$C$5:$C$404,H$3,Task!$K$5:$K$404,"Bị chặn")>0,"Bị chặn",IF(COUNTIFS(Task!$A$5:$A$404,$A9,Task!$C$5:$C$404,H$3,Task!$K$5:$K$404,"Hoàn thành")+COUNTIFS(Task!$A$5:$A$404,$A9,Task!$C$5:$C$404,H$3,Task!$K$5:$K$404,"Đang làm")>0,"Đang làm","Chưa"))))) | I9: =IF($A9="","",IF((COUNTIFS(Task!$A$5:$A$404,$A9,Task!$C$5:$C$404,I$3)-COUNTIFS(Task!$A$5:$A$404,$A9,Task!$C$5:$C$404,I$3,Task!$K$5:$K$404,"Không áp dụng"))=0,"–",IF(COUNTIFS(Task!$A$5:$A$404,$A9,Task!$C$5:$C$404,I$3,Task!$K$5:$K$404,"Hoàn thành")=(COUNTIFS(Task!$A$5:$A$404,$A9,Task!$C$5:$C$404,I$3)-COUNTIFS(Task!$A$5:$A$404,$A9,Task!$C$5:$C$404,I$3,Task!$K$5:$K$404,"Không áp dụng")),"Xong",IF(COUNTIFS(Task!$A$5:$A$404,$A9,Task!$C$5:$C$404,I$3,Task!$K$5:$K$404,"Bị chặn")>0,"Bị chặn",IF(COUNTIFS(Task!$A$5:$A$404,$A9,Task!$C$5:$C$404,I$3,Task!$K$5:$K$404,"Hoàn thành")+COUNTIFS(Task!$A$5:$A$404,$A9,Task!$C$5:$C$404,I$3,Task!$K$5:$K$404,"Đang làm")>0,"Đang làm","Chưa"))))) | J9: =IF($A9="","",IF((COUNTIFS(Task!$A$5:$A$404,$A9,Task!$C$5:$C$404,J$3)-COUNTIFS(Task!$A$5:$A$404,$A9,Task!$C$5:$C$404,J$3,Task!$K$5:$K$404,"Không áp dụng"))=0,"–",IF(COUNTIFS(Task!$A$5:$A$404,$A9,Task!$C$5:$C$404,J$3,Task!$K$5:$K$404,"Hoàn thành")=(COUNTIFS(Task!$A$5:$A$404,$A9,Task!$C$5:$C$404,J$3)-COUNTIFS(Task!$A$5:$A$404,$A9,Task!$C$5:$C$404,J$3,Task!$K$5:$K$404,"Không áp dụng")),"Xong",IF(COUNTIFS(Task!$A$5:$A$404,$A9,Task!$C$5:$C$404,J$3,Task!$K$5:$K$404,"Bị chặn")>0,"Bị chặn",IF(COUNTIFS(Task!$A$5:$A$404,$A9,Task!$C$5:$C$404,J$3,Task!$K$5:$K$404,"Hoàn thành")+COUNTIFS(Task!$A$5:$A$404,$A9,Task!$C$5:$C$404,J$3,Task!$K$5:$K$404,"Đang làm")>0,"Đang làm","Chưa"))))) | K9: =IF($A9="","",IF((COUNTIFS(Task!$A$5:$A$404,$A9,Task!$C$5:$C$404,K$3)-COUNTIFS(Task!$A$5:$A$404,$A9,Task!$C$5:$C$404,K$3,Task!$K$5:$K$404,"Không áp dụng"))=0,"–",IF(COUNTIFS(Task!$A$5:$A$404,$A9,Task!$C$5:$C$404,K$3,Task!$K$5:$K$404,"Hoàn thành")=(COUNTIFS(Task!$A$5:$A$404,$A9,Task!$C$5:$C$404,K$3)-COUNTIFS(Task!$A$5:$A$404,$A9,Task!$C$5:$C$404,K$3,Task!$K$5:$K$404,"Không áp dụng")),"Xong",IF(COUNTIFS(Task!$A$5:$A$404,$A9,Task!$C$5:$C$404,K$3,Task!$K$5:$K$404,"Bị chặn")>0,"Bị chặn",IF(COUNTIFS(Task!$A$5:$A$404,$A9,Task!$C$5:$C$404,K$3,Task!$K$5:$K$404,"Hoàn thành")+COUNTIFS(Task!$A$5:$A$404,$A9,Task!$C$5:$C$404,K$3,Task!$K$5:$K$404,"Đang làm")>0,"Đang làm","Chưa"))))) | L9: =IF($A9="","",IF((COUNTIFS(Task!$A$5:$A$404,$A9,Task!$C$5:$C$404,L$3)-COUNTIFS(Task!$A$5:$A$404,$A9,Task!$C$5:$C$404,L$3,Task!$K$5:$K$404,"Không áp dụng"))=0,"–",IF(COUNTIFS(Task!$A$5:$A$404,$A9,Task!$C$5:$C$404,L$3,Task!$K$5:$K$404,"Hoàn thành")=(COUNTIFS(Task!$A$5:$A$404,$A9,Task!$C$5:$C$404,L$3)-COUNTIFS(Task!$A$5:$A$404,$A9,Task!$C$5:$C$404,L$3,Task!$K$5:$K$404,"Không áp dụng")),"Xong",IF(COUNTIFS(Task!$A$5:$A$404,$A9,Task!$C$5:$C$404,L$3,Task!$K$5:$K$404,"Bị chặn")>0,"Bị chặn",IF(COUNTIFS(Task!$A$5:$A$404,$A9,Task!$C$5:$C$404,L$3,Task!$K$5:$K$404,"Hoàn thành")+COUNTIFS(Task!$A$5:$A$404,$A9,Task!$C$5:$C$404,L$3,Task!$K$5:$K$404,"Đang làm")>0,"Đang làm","Chưa"))))) | M9: =IF($A9="","",IF((COUNTIFS(Task!$A$5:$A$404,$A9,Task!$C$5:$C$404,M$3)-COUNTIFS(Task!$A$5:$A$404,$A9,Task!$C$5:$C$404,M$3,Task!$K$5:$K$404,"Không áp dụng"))=0,"–",IF(COUNTIFS(Task!$A$5:$A$404,$A9,Task!$C$5:$C$404,M$3,Task!$K$5:$K$404,"Hoàn thành")=(COUNTIFS(Task!$A$5:$A$404,$A9,Task!$C$5:$C$404,M$3)-COUNTIFS(Task!$A$5:$A$404,$A9,Task!$C$5:$C$404,M$3,Task!$K$5:$K$404,"Không áp dụng")),"Xong",IF(COUNTIFS(Task!$A$5:$A$404,$A9,Task!$C$5:$C$404,M$3,Task!$K$5:$K$404,"Bị chặn")>0,"Bị chặn",IF(COUNTIFS(Task!$A$5:$A$404,$A9,Task!$C$5:$C$404,M$3,Task!$K$5:$K$404,"Hoàn thành")+COUNTIFS(Task!$A$5:$A$404,$A9,Task!$C$5:$C$404,M$3,Task!$K$5:$K$404,"Đang làm")>0,"Đang làm","Chưa"))))) | N9: =IF($A9="","",IF(F9<>"Xong",1,IF(G9<>"Xong",2,IF(H9<>"Xong",3,IF(I9<>"Xong",4,IF(J9<>"Xong",5,IF(K9<>"Xong",6,IF(L9<>"Xong",7,IF(M9<>"Xong",8,9))))))))) | O9: =IF($A9="","",IF($N9=9,"Hoàn tất",INDEX('Quy trình'!$B$5:$B$12,$N9))) | P9: =IF($A9="","",COUNTIFS(Task!$A$5:$A$404,$A9)-COUNTIFS(Task!$A$5:$A$404,$A9,Task!$K$5:$K$404,"Không áp dụng")) | Q9: =IF($A9="","",COUNTIFS(Task!$A$5:$A$404,$A9,Task!$K$5:$K$404,"Hoàn thành")) | R9: =IF($A9="","",Q9/MAX(P9,COUNTA('Mẫu task'!$A$5:$A$64))) | S9: =IF($A9="","",SUMIFS(Task!$O$5:$O$404,Task!$A$5:$A$404,$A9)) | T9: =IF($A9="","",COUNTIFS(Task!$A$5:$A$404,$A9,Task!$K$5:$K$404,"Bị chặn")) | U9: =IF($A9="","",IF(P9=0,"Chưa có task",IF(T9>0,"Bị chặn",IF(S9>0,"Có việc trễ",IF(N9=9,"Hoàn tất","Đúng tiến độ"))))) | V9: =IF($A9="","",IFERROR(INDEX('Chấm điểm'!$D$16:$M$16,MATCH($A9,'Chấm điểm'!$D$4:$M$4,0)),""))
F10: =IF($A10="","",IF((COUNTIFS(Task!$A$5:$A$404,$A10,Task!$C$5:$C$404,F$3)-COUNTIFS(Task!$A$5:$A$404,$A10,Task!$C$5:$C$404,F$3,Task!$K$5:$K$404,"Không áp dụng"))=0,"–",IF(COUNTIFS(Task!$A$5:$A$404,$A10,Task!$C$5:$C$404,F$3,Task!$K$5:$K$404,"Hoàn thành")=(COUNTIFS(Task!$A$5:$A$404,$A10,Task!$C$5:$C$404,F$3)-COUNTIFS(Task!$A$5:$A$404,$A10,Task!$C$5:$C$404,F$3,Task!$K$5:$K$404,"Không áp dụng")),"Xong",IF(COUNTIFS(Task!$A$5:$A$404,$A10,Task!$C$5:$C$404,F$3,Task!$K$5:$K$404,"Bị chặn")>0,"Bị chặn",IF(COUNTIFS(Task!$A$5:$A$404,$A10,Task!$C$5:$C$404,F$3,Task!$K$5:$K$404,"Hoàn thành")+COUNTIFS(Task!$A$5:$A$404,$A10,Task!$C$5:$C$404,F$3,Task!$K$5:$K$404,"Đang làm")>0,"Đang làm","Chưa"))))) | G10: =IF($A10="","",IF((COUNTIFS(Task!$A$5:$A$404,$A10,Task!$C$5:$C$404,G$3)-COUNTIFS(Task!$A$5:$A$404,$A10,Task!$C$5:$C$404,G$3,Task!$K$5:$K$404,"Không áp dụng"))=0,"–",IF(COUNTIFS(Task!$A$5:$A$404,$A10,Task!$C$5:$C$404,G$3,Task!$K$5:$K$404,"Hoàn thành")=(COUNTIFS(Task!$A$5:$A$404,$A10,Task!$C$5:$C$404,G$3)-COUNTIFS(Task!$A$5:$A$404,$A10,Task!$C$5:$C$404,G$3,Task!$K$5:$K$404,"Không áp dụng")),"Xong",IF(COUNTIFS(Task!$A$5:$A$404,$A10,Task!$C$5:$C$404,G$3,Task!$K$5:$K$404,"Bị chặn")>0,"Bị chặn",IF(COUNTIFS(Task!$A$5:$A$404,$A10,Task!$C$5:$C$404,G$3,Task!$K$5:$K$404,"Hoàn thành")+COUNTIFS(Task!$A$5:$A$404,$A10,Task!$C$5:$C$404,G$3,Task!$K$5:$K$404,"Đang làm")>0,"Đang làm","Chưa"))))) | H10: =IF($A10="","",IF((COUNTIFS(Task!$A$5:$A$404,$A10,Task!$C$5:$C$404,H$3)-COUNTIFS(Task!$A$5:$A$404,$A10,Task!$C$5:$C$404,H$3,Task!$K$5:$K$404,"Không áp dụng"))=0,"–",IF(COUNTIFS(Task!$A$5:$A$404,$A10,Task!$C$5:$C$404,H$3,Task!$K$5:$K$404,"Hoàn thành")=(COUNTIFS(Task!$A$5:$A$404,$A10,Task!$C$5:$C$404,H$3)-COUNTIFS(Task!$A$5:$A$404,$A10,Task!$C$5:$C$404,H$3,Task!$K$5:$K$404,"Không áp dụng")),"Xong",IF(COUNTIFS(Task!$A$5:$A$404,$A10,Task!$C$5:$C$404,H$3,Task!$K$5:$K$404,"Bị chặn")>0,"Bị chặn",IF(COUNTIFS(Task!$A$5:$A$404,$A10,Task!$C$5:$C$404,H$3,Task!$K$5:$K$404,"Hoàn thành")+COUNTIFS(Task!$A$5:$A$404,$A10,Task!$C$5:$C$404,H$3,Task!$K$5:$K$404,"Đang làm")>0,"Đang làm","Chưa"))))) | I10: =IF($A10="","",IF((COUNTIFS(Task!$A$5:$A$404,$A10,Task!$C$5:$C$404,I$3)-COUNTIFS(Task!$A$5:$A$404,$A10,Task!$C$5:$C$404,I$3,Task!$K$5:$K$404,"Không áp dụng"))=0,"–",IF(COUNTIFS(Task!$A$5:$A$404,$A10,Task!$C$5:$C$404,I$3,Task!$K$5:$K$404,"Hoàn thành")=(COUNTIFS(Task!$A$5:$A$404,$A10,Task!$C$5:$C$404,I$3)-COUNTIFS(Task!$A$5:$A$404,$A10,Task!$C$5:$C$404,I$3,Task!$K$5:$K$404,"Không áp dụng")),"Xong",IF(COUNTIFS(Task!$A$5:$A$404,$A10,Task!$C$5:$C$404,I$3,Task!$K$5:$K$404,"Bị chặn")>0,"Bị chặn",IF(COUNTIFS(Task!$A$5:$A$404,$A10,Task!$C$5:$C$404,I$3,Task!$K$5:$K$404,"Hoàn thành")+COUNTIFS(Task!$A$5:$A$404,$A10,Task!$C$5:$C$404,I$3,Task!$K$5:$K$404,"Đang làm")>0,"Đang làm","Chưa"))))) | J10: =IF($A10="","",IF((COUNTIFS(Task!$A$5:$A$404,$A10,Task!$C$5:$C$404,J$3)-COUNTIFS(Task!$A$5:$A$404,$A10,Task!$C$5:$C$404,J$3,Task!$K$5:$K$404,"Không áp dụng"))=0,"–",IF(COUNTIFS(Task!$A$5:$A$404,$A10,Task!$C$5:$C$404,J$3,Task!$K$5:$K$404,"Hoàn thành")=(COUNTIFS(Task!$A$5:$A$404,$A10,Task!$C$5:$C$404,J$3)-COUNTIFS(Task!$A$5:$A$404,$A10,Task!$C$5:$C$404,J$3,Task!$K$5:$K$404,"Không áp dụng")),"Xong",IF(COUNTIFS(Task!$A$5:$A$404,$A10,Task!$C$5:$C$404,J$3,Task!$K$5:$K$404,"Bị chặn")>0,"Bị chặn",IF(COUNTIFS(Task!$A$5:$A$404,$A10,Task!$C$5:$C$404,J$3,Task!$K$5:$K$404,"Hoàn thành")+COUNTIFS(Task!$A$5:$A$404,$A10,Task!$C$5:$C$404,J$3,Task!$K$5:$K$404,"Đang làm")>0,"Đang làm","Chưa"))))) | K10: =IF($A10="","",IF((COUNTIFS(Task!$A$5:$A$404,$A10,Task!$C$5:$C$404,K$3)-COUNTIFS(Task!$A$5:$A$404,$A10,Task!$C$5:$C$404,K$3,Task!$K$5:$K$404,"Không áp dụng"))=0,"–",IF(COUNTIFS(Task!$A$5:$A$404,$A10,Task!$C$5:$C$404,K$3,Task!$K$5:$K$404,"Hoàn thành")=(COUNTIFS(Task!$A$5:$A$404,$A10,Task!$C$5:$C$404,K$3)-COUNTIFS(Task!$A$5:$A$404,$A10,Task!$C$5:$C$404,K$3,Task!$K$5:$K$404,"Không áp dụng")),"Xong",IF(COUNTIFS(Task!$A$5:$A$404,$A10,Task!$C$5:$C$404,K$3,Task!$K$5:$K$404,"Bị chặn")>0,"Bị chặn",IF(COUNTIFS(Task!$A$5:$A$404,$A10,Task!$C$5:$C$404,K$3,Task!$K$5:$K$404,"Hoàn thành")+COUNTIFS(Task!$A$5:$A$404,$A10,Task!$C$5:$C$404,K$3,Task!$K$5:$K$404,"Đang làm")>0,"Đang làm","Chưa"))))) | L10: =IF($A10="","",IF((COUNTIFS(Task!$A$5:$A$404,$A10,Task!$C$5:$C$404,L$3)-COUNTIFS(Task!$A$5:$A$404,$A10,Task!$C$5:$C$404,L$3,Task!$K$5:$K$404,"Không áp dụng"))=0,"–",IF(COUNTIFS(Task!$A$5:$A$404,$A10,Task!$C$5:$C$404,L$3,Task!$K$5:$K$404,"Hoàn thành")=(COUNTIFS(Task!$A$5:$A$404,$A10,Task!$C$5:$C$404,L$3)-COUNTIFS(Task!$A$5:$A$404,$A10,Task!$C$5:$C$404,L$3,Task!$K$5:$K$404,"Không áp dụng")),"Xong",IF(COUNTIFS(Task!$A$5:$A$404,$A10,Task!$C$5:$C$404,L$3,Task!$K$5:$K$404,"Bị chặn")>0,"Bị chặn",IF(COUNTIFS(Task!$A$5:$A$404,$A10,Task!$C$5:$C$404,L$3,Task!$K$5:$K$404,"Hoàn thành")+COUNTIFS(Task!$A$5:$A$404,$A10,Task!$C$5:$C$404,L$3,Task!$K$5:$K$404,"Đang làm")>0,"Đang làm","Chưa"))))) | M10: =IF($A10="","",IF((COUNTIFS(Task!$A$5:$A$404,$A10,Task!$C$5:$C$404,M$3)-COUNTIFS(Task!$A$5:$A$404,$A10,Task!$C$5:$C$404,M$3,Task!$K$5:$K$404,"Không áp dụng"))=0,"–",IF(COUNTIFS(Task!$A$5:$A$404,$A10,Task!$C$5:$C$404,M$3,Task!$K$5:$K$404,"Hoàn thành")=(COUNTIFS(Task!$A$5:$A$404,$A10,Task!$C$5:$C$404,M$3)-COUNTIFS(Task!$A$5:$A$404,$A10,Task!$C$5:$C$404,M$3,Task!$K$5:$K$404,"Không áp dụng")),"Xong",IF(COUNTIFS(Task!$A$5:$A$404,$A10,Task!$C$5:$C$404,M$3,Task!$K$5:$K$404,"Bị chặn")>0,"Bị chặn",IF(COUNTIFS(Task!$A$5:$A$404,$A10,Task!$C$5:$C$404,M$3,Task!$K$5:$K$404,"Hoàn thành")+COUNTIFS(Task!$A$5:$A$404,$A10,Task!$C$5:$C$404,M$3,Task!$K$5:$K$404,"Đang làm")>0,"Đang làm","Chưa"))))) | N10: =IF($A10="","",IF(F10<>"Xong",1,IF(G10<>"Xong",2,IF(H10<>"Xong",3,IF(I10<>"Xong",4,IF(J10<>"Xong",5,IF(K10<>"Xong",6,IF(L10<>"Xong",7,IF(M10<>"Xong",8,9))))))))) | O10: =IF($A10="","",IF($N10=9,"Hoàn tất",INDEX('Quy trình'!$B$5:$B$12,$N10))) | P10: =IF($A10="","",COUNTIFS(Task!$A$5:$A$404,$A10)-COUNTIFS(Task!$A$5:$A$404,$A10,Task!$K$5:$K$404,"Không áp dụng")) | Q10: =IF($A10="","",COUNTIFS(Task!$A$5:$A$404,$A10,Task!$K$5:$K$404,"Hoàn thành")) | R10: =IF($A10="","",Q10/MAX(P10,COUNTA('Mẫu task'!$A$5:$A$64))) | S10: =IF($A10="","",SUMIFS(Task!$O$5:$O$404,Task!$A$5:$A$404,$A10)) | T10: =IF($A10="","",COUNTIFS(Task!$A$5:$A$404,$A10,Task!$K$5:$K$404,"Bị chặn")) | U10: =IF($A10="","",IF(P10=0,"Chưa có task",IF(T10>0,"Bị chặn",IF(S10>0,"Có việc trễ",IF(N10=9,"Hoàn tất","Đúng tiến độ"))))) | V10: =IF($A10="","",IFERROR(INDEX('Chấm điểm'!$D$16:$M$16,MATCH($A10,'Chấm điểm'!$D$4:$M$4,0)),""))
F11: =IF($A11="","",IF((COUNTIFS(Task!$A$5:$A$404,$A11,Task!$C$5:$C$404,F$3)-COUNTIFS(Task!$A$5:$A$404,$A11,Task!$C$5:$C$404,F$3,Task!$K$5:$K$404,"Không áp dụng"))=0,"–",IF(COUNTIFS(Task!$A$5:$A$404,$A11,Task!$C$5:$C$404,F$3,Task!$K$5:$K$404,"Hoàn thành")=(COUNTIFS(Task!$A$5:$A$404,$A11,Task!$C$5:$C$404,F$3)-COUNTIFS(Task!$A$5:$A$404,$A11,Task!$C$5:$C$404,F$3,Task!$K$5:$K$404,"Không áp dụng")),"Xong",IF(COUNTIFS(Task!$A$5:$A$404,$A11,Task!$C$5:$C$404,F$3,Task!$K$5:$K$404,"Bị chặn")>0,"Bị chặn",IF(COUNTIFS(Task!$A$5:$A$404,$A11,Task!$C$5:$C$404,F$3,Task!$K$5:$K$404,"Hoàn thành")+COUNTIFS(Task!$A$5:$A$404,$A11,Task!$C$5:$C$404,F$3,Task!$K$5:$K$404,"Đang làm")>0,"Đang làm","Chưa"))))) | G11: =IF($A11="","",IF((COUNTIFS(Task!$A$5:$A$404,$A11,Task!$C$5:$C$404,G$3)-COUNTIFS(Task!$A$5:$A$404,$A11,Task!$C$5:$C$404,G$3,Task!$K$5:$K$404,"Không áp dụng"))=0,"–",IF(COUNTIFS(Task!$A$5:$A$404,$A11,Task!$C$5:$C$404,G$3,Task!$K$5:$K$404,"Hoàn thành")=(COUNTIFS(Task!$A$5:$A$404,$A11,Task!$C$5:$C$404,G$3)-COUNTIFS(Task!$A$5:$A$404,$A11,Task!$C$5:$C$404,G$3,Task!$K$5:$K$404,"Không áp dụng")),"Xong",IF(COUNTIFS(Task!$A$5:$A$404,$A11,Task!$C$5:$C$404,G$3,Task!$K$5:$K$404,"Bị chặn")>0,"Bị chặn",IF(COUNTIFS(Task!$A$5:$A$404,$A11,Task!$C$5:$C$404,G$3,Task!$K$5:$K$404,"Hoàn thành")+COUNTIFS(Task!$A$5:$A$404,$A11,Task!$C$5:$C$404,G$3,Task!$K$5:$K$404,"Đang làm")>0,"Đang làm","Chưa"))))) | H11: =IF($A11="","",IF((COUNTIFS(Task!$A$5:$A$404,$A11,Task!$C$5:$C$404,H$3)-COUNTIFS(Task!$A$5:$A$404,$A11,Task!$C$5:$C$404,H$3,Task!$K$5:$K$404,"Không áp dụng"))=0,"–",IF(COUNTIFS(Task!$A$5:$A$404,$A11,Task!$C$5:$C$404,H$3,Task!$K$5:$K$404,"Hoàn thành")=(COUNTIFS(Task!$A$5:$A$404,$A11,Task!$C$5:$C$404,H$3)-COUNTIFS(Task!$A$5:$A$404,$A11,Task!$C$5:$C$404,H$3,Task!$K$5:$K$404,"Không áp dụng")),"Xong",IF(COUNTIFS(Task!$A$5:$A$404,$A11,Task!$C$5:$C$404,H$3,Task!$K$5:$K$404,"Bị chặn")>0,"Bị chặn",IF(COUNTIFS(Task!$A$5:$A$404,$A11,Task!$C$5:$C$404,H$3,Task!$K$5:$K$404,"Hoàn thành")+COUNTIFS(Task!$A$5:$A$404,$A11,Task!$C$5:$C$404,H$3,Task!$K$5:$K$404,"Đang làm")>0,"Đang làm","Chưa"))))) | I11: =IF($A11="","",IF((COUNTIFS(Task!$A$5:$A$404,$A11,Task!$C$5:$C$404,I$3)-COUNTIFS(Task!$A$5:$A$404,$A11,Task!$C$5:$C$404,I$3,Task!$K$5:$K$404,"Không áp dụng"))=0,"–",IF(COUNTIFS(Task!$A$5:$A$404,$A11,Task!$C$5:$C$404,I$3,Task!$K$5:$K$404,"Hoàn thành")=(COUNTIFS(Task!$A$5:$A$404,$A11,Task!$C$5:$C$404,I$3)-COUNTIFS(Task!$A$5:$A$404,$A11,Task!$C$5:$C$404,I$3,Task!$K$5:$K$404,"Không áp dụng")),"Xong",IF(COUNTIFS(Task!$A$5:$A$404,$A11,Task!$C$5:$C$404,I$3,Task!$K$5:$K$404,"Bị chặn")>0,"Bị chặn",IF(COUNTIFS(Task!$A$5:$A$404,$A11,Task!$C$5:$C$404,I$3,Task!$K$5:$K$404,"Hoàn thành")+COUNTIFS(Task!$A$5:$A$404,$A11,Task!$C$5:$C$404,I$3,Task!$K$5:$K$404,"Đang làm")>0,"Đang làm","Chưa"))))) | J11: =IF($A11="","",IF((COUNTIFS(Task!$A$5:$A$404,$A11,Task!$C$5:$C$404,J$3)-COUNTIFS(Task!$A$5:$A$404,$A11,Task!$C$5:$C$404,J$3,Task!$K$5:$K$404,"Không áp dụng"))=0,"–",IF(COUNTIFS(Task!$A$5:$A$404,$A11,Task!$C$5:$C$404,J$3,Task!$K$5:$K$404,"Hoàn thành")=(COUNTIFS(Task!$A$5:$A$404,$A11,Task!$C$5:$C$404,J$3)-COUNTIFS(Task!$A$5:$A$404,$A11,Task!$C$5:$C$404,J$3,Task!$K$5:$K$404,"Không áp dụng")),"Xong",IF(COUNTIFS(Task!$A$5:$A$404,$A11,Task!$C$5:$C$404,J$3,Task!$K$5:$K$404,"Bị chặn")>0,"Bị chặn",IF(COUNTIFS(Task!$A$5:$A$404,$A11,Task!$C$5:$C$404,J$3,Task!$K$5:$K$404,"Hoàn thành")+COUNTIFS(Task!$A$5:$A$404,$A11,Task!$C$5:$C$404,J$3,Task!$K$5:$K$404,"Đang làm")>0,"Đang làm","Chưa"))))) | K11: =IF($A11="","",IF((COUNTIFS(Task!$A$5:$A$404,$A11,Task!$C$5:$C$404,K$3)-COUNTIFS(Task!$A$5:$A$404,$A11,Task!$C$5:$C$404,K$3,Task!$K$5:$K$404,"Không áp dụng"))=0,"–",IF(COUNTIFS(Task!$A$5:$A$404,$A11,Task!$C$5:$C$404,K$3,Task!$K$5:$K$404,"Hoàn thành")=(COUNTIFS(Task!$A$5:$A$404,$A11,Task!$C$5:$C$404,K$3)-COUNTIFS(Task!$A$5:$A$404,$A11,Task!$C$5:$C$404,K$3,Task!$K$5:$K$404,"Không áp dụng")),"Xong",IF(COUNTIFS(Task!$A$5:$A$404,$A11,Task!$C$5:$C$404,K$3,Task!$K$5:$K$404,"Bị chặn")>0,"Bị chặn",IF(COUNTIFS(Task!$A$5:$A$404,$A11,Task!$C$5:$C$404,K$3,Task!$K$5:$K$404,"Hoàn thành")+COUNTIFS(Task!$A$5:$A$404,$A11,Task!$C$5:$C$404,K$3,Task!$K$5:$K$404,"Đang làm")>0,"Đang làm","Chưa"))))) | L11: =IF($A11="","",IF((COUNTIFS(Task!$A$5:$A$404,$A11,Task!$C$5:$C$404,L$3)-COUNTIFS(Task!$A$5:$A$404,$A11,Task!$C$5:$C$404,L$3,Task!$K$5:$K$404,"Không áp dụng"))=0,"–",IF(COUNTIFS(Task!$A$5:$A$404,$A11,Task!$C$5:$C$404,L$3,Task!$K$5:$K$404,"Hoàn thành")=(COUNTIFS(Task!$A$5:$A$404,$A11,Task!$C$5:$C$404,L$3)-COUNTIFS(Task!$A$5:$A$404,$A11,Task!$C$5:$C$404,L$3,Task!$K$5:$K$404,"Không áp dụng")),"Xong",IF(COUNTIFS(Task!$A$5:$A$404,$A11,Task!$C$5:$C$404,L$3,Task!$K$5:$K$404,"Bị chặn")>0,"Bị chặn",IF(COUNTIFS(Task!$A$5:$A$404,$A11,Task!$C$5:$C$404,L$3,Task!$K$5:$K$404,"Hoàn thành")+COUNTIFS(Task!$A$5:$A$404,$A11,Task!$C$5:$C$404,L$3,Task!$K$5:$K$404,"Đang làm")>0,"Đang làm","Chưa"))))) | M11: =IF($A11="","",IF((COUNTIFS(Task!$A$5:$A$404,$A11,Task!$C$5:$C$404,M$3)-COUNTIFS(Task!$A$5:$A$404,$A11,Task!$C$5:$C$404,M$3,Task!$K$5:$K$404,"Không áp dụng"))=0,"–",IF(COUNTIFS(Task!$A$5:$A$404,$A11,Task!$C$5:$C$404,M$3,Task!$K$5:$K$404,"Hoàn thành")=(COUNTIFS(Task!$A$5:$A$404,$A11,Task!$C$5:$C$404,M$3)-COUNTIFS(Task!$A$5:$A$404,$A11,Task!$C$5:$C$404,M$3,Task!$K$5:$K$404,"Không áp dụng")),"Xong",IF(COUNTIFS(Task!$A$5:$A$404,$A11,Task!$C$5:$C$404,M$3,Task!$K$5:$K$404,"Bị chặn")>0,"Bị chặn",IF(COUNTIFS(Task!$A$5:$A$404,$A11,Task!$C$5:$C$404,M$3,Task!$K$5:$K$404,"Hoàn thành")+COUNTIFS(Task!$A$5:$A$404,$A11,Task!$C$5:$C$404,M$3,Task!$K$5:$K$404,"Đang làm")>0,"Đang làm","Chưa"))))) | N11: =IF($A11="","",IF(F11<>"Xong",1,IF(G11<>"Xong",2,IF(H11<>"Xong",3,IF(I11<>"Xong",4,IF(J11<>"Xong",5,IF(K11<>"Xong",6,IF(L11<>"Xong",7,IF(M11<>"Xong",8,9))))))))) | O11: =IF($A11="","",IF($N11=9,"Hoàn tất",INDEX('Quy trình'!$B$5:$B$12,$N11))) | P11: =IF($A11="","",COUNTIFS(Task!$A$5:$A$404,$A11)-COUNTIFS(Task!$A$5:$A$404,$A11,Task!$K$5:$K$404,"Không áp dụng")) | Q11: =IF($A11="","",COUNTIFS(Task!$A$5:$A$404,$A11,Task!$K$5:$K$404,"Hoàn thành")) | R11: =IF($A11="","",Q11/MAX(P11,COUNTA('Mẫu task'!$A$5:$A$64))) | S11: =IF($A11="","",SUMIFS(Task!$O$5:$O$404,Task!$A$5:$A$404,$A11)) | T11: =IF($A11="","",COUNTIFS(Task!$A$5:$A$404,$A11,Task!$K$5:$K$404,"Bị chặn")) | U11: =IF($A11="","",IF(P11=0,"Chưa có task",IF(T11>0,"Bị chặn",IF(S11>0,"Có việc trễ",IF(N11=9,"Hoàn tất","Đúng tiến độ"))))) | V11: =IF($A11="","",IFERROR(INDEX('Chấm điểm'!$D$16:$M$16,MATCH($A11,'Chấm điểm'!$D$4:$M$4,0)),""))
